{
  "test_timestamp": "20250630_143205",
  "test_config": {
    "base_url": "http://localhost",
    "port": 80,
    "num_concurrent_users": 100,
    "num_requests_per_user": 50,
    "ramp_up_time": 30,
    "test_duration": 300,
    "request_timeout": 30,
    "think_time": 0.5
  },
  "results": {
    "total_requests": 5000,
    "successful_requests": 0,
    "failed_requests": 5000,
    "average_response_time": 0.004692693471908569,
    "median_response_time": 0.0034044981002807617,
    "p95_response_time": 0.012687981128692627,
    "p99_response_time": 0.01683781862258911,
    "min_response_time": 0.0004470348358154297,
    "max_response_time": 0.06161212921142578,
    "requests_per_second": 91.14674527550872,
    "error_rate": 100.0,
    "test_duration": 54.856594,
    "concurrent_users": 100
  },
  "detailed_results": [
    {
      "timestamp": "2025-06-30 14:32:00.222655",
      "response_time": 0.002393960952758789,
      "status_code": 0,
      "success": false,
      "error_message": "HTTPConnectionPool(host='localhost', port=80): Max retries exceeded with url: /api/ask (Caused by NewConnectionError('<urllib3.connection.HTTPConnection object at 0x104f746b0>: Failed to establish a new connection: [Errno 61] Connection refused'))",
      "response_size": 0
    },
    {
      "timestamp": "2025-06-30 14:32:00.260667",
      "response_time": 0.0037376880645751953,
      "status_code": 0,
      "success": false,
      "error_message": "HTTPConnectionPool(host='localhost', port=80): Max retries exceeded with url: /api/ask (Caused by NewConnectionError('<urllib3.connection.HTTPConnection object at 0x104f76140>: Failed to establish a new connection: [Errno 61] Connection refused'))",
      "response_size": 0
    },
    {
      "timestamp": "2025-06-30 14:32:00.260974",
      "response_time": 0.0037720203399658203,
      "status_code": 0,
      "success": false,
      "error_message": "HTTPConnectionPool(host='localhost', port=80): Max retries exceeded with url: /api/ask (Caused by NewConnectionError('<urllib3.connection.HTTPConnection object at 0x104f74490>: Failed to establish a new connection: [Errno 61] Connection refused'))",
      "response_size": 0
    },
    {
      "timestamp": "2025-06-30 14:32:00.266765",
      "response_time": 0.007352113723754883,
      "status_code": 0,
      "success": false,
      "error_message": "HTTPConnectionPool(host='localhost', port=80): Max retries exceeded with url: /metrics (Caused by NewConnectionError('<urllib3.connection.HTTPConnection object at 0x104f746b0>: Failed to establish a new connection: [Errno 61] Connection refused'))",
      "response_size": 0
    },
    {
      "timestamp": "2025-06-30 14:32:00.268918",
      "response_time": 0.00527191162109375,
      "status_code": 0,
      "success": false,
      "error_message": "HTTPConnectionPool(host='localhost', port=80): Max retries exceeded with url: /api/ask (Caused by NewConnectionError('<urllib3.connection.HTTPConnection object at 0x104f768b0>: Failed to establish a new connection: [Errno 61] Connection refused'))",
      "response_size": 0
    },
    {
      "timestamp": "2025-06-30 14:32:00.269113",
      "response_time": 0.005201816558837891,
      "status_code": 0,
      "success": false,
      "error_message": "HTTPConnectionPool(host='localhost', port=80): Max retries exceeded with url: /metrics (Caused by NewConnectionError('<urllib3.connection.HTTPConnection object at 0x104f74490>: Failed to establish a new connection: [Errno 61] Connection refused'))",
      "response_size": 0
    },
    {
      "timestamp": "2025-06-30 14:32:00.266643",
      "response_time": 0.007995128631591797,
      "status_code": 0,
      "success": false,
      "error_message": "HTTPConnectionPool(host='localhost', port=80): Max retries exceeded with url: /api/ask (Caused by NewConnectionError('<urllib3.connection.HTTPConnection object at 0x104f75d00>: Failed to establish a new connection: [Errno 61] Connection refused'))",
      "response_size": 0
    },
    {
      "timestamp": "2025-06-30 14:32:00.269036",
      "response_time": 0.005671977996826172,
      "status_code": 0,
      "success": false,
      "error_message": "HTTPConnectionPool(host='localhost', port=80): Max retries exceeded with url: /api/ask (Caused by NewConnectionError('<urllib3.connection.HTTPConnection object at 0x104f76140>: Failed to establish a new connection: [Errno 61] Connection refused'))",
      "response_size": 0
    },
    {
      "timestamp": "2025-06-30 14:32:00.270363",
      "response_time": 0.004690885543823242,
      "status_code": 0,
      "success": false,
      "error_message": "HTTPConnectionPool(host='localhost', port=80): Max retries exceeded with url: /api/ask (Caused by NewConnectionError('<urllib3.connection.HTTPConnection object at 0x104f75e10>: Failed to establish a new connection: [Errno 61] Connection refused'))",
      "response_size": 0
    },
    {
      "timestamp": "2025-06-30 14:32:00.294520",
      "response_time": 0.002131938934326172,
      "status_code": 0,
      "success": false,
      "error_message": "HTTPConnectionPool(host='localhost', port=80): Max retries exceeded with url: /health (Caused by NewConnectionError('<urllib3.connection.HTTPConnection object at 0x104f74e20>: Failed to establish a new connection: [Errno 61] Connection refused'))",
      "response_size": 0
    },
    {
      "timestamp": "2025-06-30 14:32:00.452506",
      "response_time": 0.006363868713378906,
      "status_code": 0,
      "success": false,
      "error_message": "HTTPConnectionPool(host='localhost', port=80): Max retries exceeded with url: /metrics (Caused by NewConnectionError('<urllib3.connection.HTTPConnection object at 0x104f76ad0>: Failed to establish a new connection: [Errno 61] Connection refused'))",
      "response_size": 0
    },
    {
      "timestamp": "2025-06-30 14:32:00.452834",
      "response_time": 0.006203889846801758,
      "status_code": 0,
      "success": false,
      "error_message": "HTTPConnectionPool(host='localhost', port=80): Max retries exceeded with url: /api/ask (Caused by NewConnectionError('<urllib3.connection.HTTPConnection object at 0x104f769c0>: Failed to establish a new connection: [Errno 61] Connection refused'))",
      "response_size": 0
    },
    {
      "timestamp": "2025-06-30 14:32:00.453668",
      "response_time": 0.0055637359619140625,
      "status_code": 0,
      "success": false,
      "error_message": "HTTPConnectionPool(host='localhost', port=80): Max retries exceeded with url: /api/ask (Caused by NewConnectionError('<urllib3.connection.HTTPConnection object at 0x104f75150>: Failed to establish a new connection: [Errno 61] Connection refused'))",
      "response_size": 0
    },
    {
      "timestamp": "2025-06-30 14:32:00.455771",
      "response_time": 0.0036890506744384766,
      "status_code": 0,
      "success": false,
      "error_message": "HTTPConnectionPool(host='localhost', port=80): Max retries exceeded with url: /api/ask (Caused by NewConnectionError('<urllib3.connection.HTTPConnection object at 0x104f75260>: Failed to establish a new connection: [Errno 61] Connection refused'))",
      "response_size": 0
    },
    {
      "timestamp": "2025-06-30 14:32:00.456149",
      "response_time": 0.0036890506744384766,
      "status_code": 0,
      "success": false,
      "error_message": "HTTPConnectionPool(host='localhost', port=80): Max retries exceeded with url: /health (Caused by NewConnectionError('<urllib3.connection.HTTPConnection object at 0x104f747c0>: Failed to establish a new connection: [Errno 61] Connection refused'))",
      "response_size": 0
    },
    {
      "timestamp": "2025-06-30 14:32:00.486318",
      "response_time": 0.0029129981994628906,
      "status_code": 0,
      "success": false,
      "error_message": "HTTPConnectionPool(host='localhost', port=80): Max retries exceeded with url: /metrics (Caused by NewConnectionError('<urllib3.connection.HTTPConnection object at 0x104f767a0>: Failed to establish a new connection: [Errno 61] Connection refused'))",
      "response_size": 0
    },
    {
      "timestamp": "2025-06-30 14:32:00.489412",
      "response_time": 0.001809835433959961,
      "status_code": 0,
      "success": false,
      "error_message": "HTTPConnectionPool(host='localhost', port=80): Max retries exceeded with url: /docs (Caused by NewConnectionError('<urllib3.connection.HTTPConnection object at 0x104f75480>: Failed to establish a new connection: [Errno 61] Connection refused'))",
      "response_size": 0
    },
    {
      "timestamp": "2025-06-30 14:32:00.722284",
      "response_time": 0.006078958511352539,
      "status_code": 0,
      "success": false,
      "error_message": "HTTPConnectionPool(host='localhost', port=80): Max retries exceeded with url: /api/ask (Caused by NewConnectionError('<urllib3.connection.HTTPConnection object at 0x104f75ae0>: Failed to establish a new connection: [Errno 61] Connection refused'))",
      "response_size": 0
    },
    {
      "timestamp": "2025-06-30 14:32:00.726611",
      "response_time": 0.004395961761474609,
      "status_code": 0,
      "success": false,
      "error_message": "HTTPConnectionPool(host='localhost', port=80): Max retries exceeded with url: /health (Caused by NewConnectionError('<urllib3.connection.HTTPConnection object at 0x104f76360>: Failed to establish a new connection: [Errno 61] Connection refused'))",
      "response_size": 0
    },
    {
      "timestamp": "2025-06-30 14:32:00.767705",
      "response_time": 0.0028688907623291016,
      "status_code": 0,
      "success": false,
      "error_message": "HTTPConnectionPool(host='localhost', port=80): Max retries exceeded with url: /api/ask (Caused by NewConnectionError('<urllib3.connection.HTTPConnection object at 0x104f779b0>: Failed to establish a new connection: [Errno 61] Connection refused'))",
      "response_size": 0
    },
    {
      "timestamp": "2025-06-30 14:32:00.769099",
      "response_time": 0.0021779537200927734,
      "status_code": 0,
      "success": false,
      "error_message": "HTTPConnectionPool(host='localhost', port=80): Max retries exceeded with url: /api/ask (Caused by NewConnectionError('<urllib3.connection.HTTPConnection object at 0x104f75590>: Failed to establish a new connection: [Errno 61] Connection refused'))",
      "response_size": 0
    },
    {
      "timestamp": "2025-06-30 14:32:00.778256",
      "response_time": 0.0025398731231689453,
      "status_code": 0,
      "success": false,
      "error_message": "HTTPConnectionPool(host='localhost', port=80): Max retries exceeded with url: /api/ask (Caused by NewConnectionError('<urllib3.connection.HTTPConnection object at 0x104f758c0>: Failed to establish a new connection: [Errno 61] Connection refused'))",
      "response_size": 0
    },
    {
      "timestamp": "2025-06-30 14:32:00.778946",
      "response_time": 0.0022430419921875,
      "status_code": 0,
      "success": false,
      "error_message": "HTTPConnectionPool(host='localhost', port=80): Max retries exceeded with url: /api/ask (Caused by NewConnectionError('<urllib3.connection.HTTPConnection object at 0x104f75480>: Failed to establish a new connection: [Errno 61] Connection refused'))",
      "response_size": 0
    },
    {
      "timestamp": "2025-06-30 14:32:00.779005",
      "response_time": 0.0023140907287597656,
      "status_code": 0,
      "success": false,
      "error_message": "HTTPConnectionPool(host='localhost', port=80): Max retries exceeded with url: /api/ask (Caused by NewConnectionError('<urllib3.connection.HTTPConnection object at 0x104f74d10>: Failed to establish a new connection: [Errno 61] Connection refused'))",
      "response_size": 0
    },
    {
      "timestamp": "2025-06-30 14:32:00.779398",
      "response_time": 0.001958131790161133,
      "status_code": 0,
      "success": false,
      "error_message": "HTTPConnectionPool(host='localhost', port=80): Max retries exceeded with url: /docs (Caused by NewConnectionError('<urllib3.connection.HTTPConnection object at 0x104f767a0>: Failed to establish a new connection: [Errno 61] Connection refused'))",
      "response_size": 0
    },
    {
      "timestamp": "2025-06-30 14:32:00.779766",
      "response_time": 0.0016827583312988281,
      "status_code": 0,
      "success": false,
      "error_message": "HTTPConnectionPool(host='localhost', port=80): Max retries exceeded with url: /api/ask (Caused by NewConnectionError('<urllib3.connection.HTTPConnection object at 0x104f747c0>: Failed to establish a new connection: [Errno 61] Connection refused'))",
      "response_size": 0
    },
    {
      "timestamp": "2025-06-30 14:32:00.800487",
      "response_time": 0.0016140937805175781,
      "status_code": 0,
      "success": false,
      "error_message": "HTTPConnectionPool(host='localhost', port=80): Max retries exceeded with url: /metrics (Caused by NewConnectionError('<urllib3.connection.HTTPConnection object at 0x104f75150>: Failed to establish a new connection: [Errno 61] Connection refused'))",
      "response_size": 0
    },
    {
      "timestamp": "2025-06-30 14:32:00.961515",
      "response_time": 0.005326032638549805,
      "status_code": 0,
      "success": false,
      "error_message": "HTTPConnectionPool(host='localhost', port=80): Max retries exceeded with url: /api/ask (Caused by NewConnectionError('<urllib3.connection.HTTPConnection object at 0x104f769c0>: Failed to establish a new connection: [Errno 61] Connection refused'))",
      "response_size": 0
    },
    {
      "timestamp": "2025-06-30 14:32:00.961197",
      "response_time": 0.006036043167114258,
      "status_code": 0,
      "success": false,
      "error_message": "HTTPConnectionPool(host='localhost', port=80): Max retries exceeded with url: /metrics (Caused by NewConnectionError('<urllib3.connection.HTTPConnection object at 0x104f77130>: Failed to establish a new connection: [Errno 61] Connection refused'))",
      "response_size": 0
    },
    {
      "timestamp": "2025-06-30 14:32:00.964990",
      "response_time": 0.0025010108947753906,
      "status_code": 0,
      "success": false,
      "error_message": "HTTPConnectionPool(host='localhost', port=80): Max retries exceeded with url: /api/ask (Caused by NewConnectionError('<urllib3.connection.HTTPConnection object at 0x104f76ad0>: Failed to establish a new connection: [Errno 61] Connection refused'))",
      "response_size": 0
    },
    {
      "timestamp": "2025-06-30 14:32:00.964553",
      "response_time": 0.0032210350036621094,
      "status_code": 0,
      "success": false,
      "error_message": "HTTPConnectionPool(host='localhost', port=80): Max retries exceeded with url: /api/ask (Caused by NewConnectionError('<urllib3.connection.HTTPConnection object at 0x104f76250>: Failed to establish a new connection: [Errno 61] Connection refused'))",
      "response_size": 0
    },
    {
      "timestamp": "2025-06-30 14:32:00.993319",
      "response_time": 0.003359079360961914,
      "status_code": 0,
      "success": false,
      "error_message": "HTTPConnectionPool(host='localhost', port=80): Max retries exceeded with url: /api/ask (Caused by NewConnectionError('<urllib3.connection.HTTPConnection object at 0x104f76140>: Failed to establish a new connection: [Errno 61] Connection refused'))",
      "response_size": 0
    },
    {
      "timestamp": "2025-06-30 14:32:00.994003",
      "response_time": 0.002975940704345703,
      "status_code": 0,
      "success": false,
      "error_message": "HTTPConnectionPool(host='localhost', port=80): Max retries exceeded with url: /api/ask (Caused by NewConnectionError('<urllib3.connection.HTTPConnection object at 0x104f77790>: Failed to establish a new connection: [Errno 61] Connection refused'))",
      "response_size": 0
    },
    {
      "timestamp": "2025-06-30 14:32:01.234578",
      "response_time": 0.0034170150756835938,
      "status_code": 0,
      "success": false,
      "error_message": "HTTPConnectionPool(host='localhost', port=80): Max retries exceeded with url: /health (Caused by NewConnectionError('<urllib3.connection.HTTPConnection object at 0x104f74160>: Failed to establish a new connection: [Errno 61] Connection refused'))",
      "response_size": 0
    },
    {
      "timestamp": "2025-06-30 14:32:01.233458",
      "response_time": 0.0046579837799072266,
      "status_code": 0,
      "success": false,
      "error_message": "HTTPConnectionPool(host='localhost', port=80): Max retries exceeded with url: /api/ask (Caused by NewConnectionError('<urllib3.connection.HTTPConnection object at 0x104f74490>: Failed to establish a new connection: [Errno 61] Connection refused'))",
      "response_size": 0
    },
    {
      "timestamp": "2025-06-30 14:32:01.275879",
      "response_time": 0.005816936492919922,
      "status_code": 0,
      "success": false,
      "error_message": "HTTPConnectionPool(host='localhost', port=80): Max retries exceeded with url: /docs (Caused by NewConnectionError('<urllib3.connection.HTTPConnection object at 0x104f77680>: Failed to establish a new connection: [Errno 61] Connection refused'))",
      "response_size": 0
    },
    {
      "timestamp": "2025-06-30 14:32:01.275638",
      "response_time": 0.006361961364746094,
      "status_code": 0,
      "success": false,
      "error_message": "HTTPConnectionPool(host='localhost', port=80): Max retries exceeded with url: /metrics (Caused by NewConnectionError('<urllib3.connection.HTTPConnection object at 0x104f74490>: Failed to establish a new connection: [Errno 61] Connection refused'))",
      "response_size": 0
    },
    {
      "timestamp": "2025-06-30 14:32:01.286424",
      "response_time": 0.002962827682495117,
      "status_code": 0,
      "success": false,
      "error_message": "HTTPConnectionPool(host='localhost', port=80): Max retries exceeded with url: /docs (Caused by NewConnectionError('<urllib3.connection.HTTPConnection object at 0x104f77ac0>: Failed to establish a new connection: [Errno 61] Connection refused'))",
      "response_size": 0
    },
    {
      "timestamp": "2025-06-30 14:32:01.286256",
      "response_time": 0.0031981468200683594,
      "status_code": 0,
      "success": false,
      "error_message": "HTTPConnectionPool(host='localhost', port=80): Max retries exceeded with url: /health (Caused by NewConnectionError('<urllib3.connection.HTTPConnection object at 0x104f76580>: Failed to establish a new connection: [Errno 61] Connection refused'))",
      "response_size": 0
    },
    {
      "timestamp": "2025-06-30 14:32:01.286604",
      "response_time": 0.0029020309448242188,
      "status_code": 0,
      "success": false,
      "error_message": "HTTPConnectionPool(host='localhost', port=80): Max retries exceeded with url: /api/ask (Caused by NewConnectionError('<urllib3.connection.HTTPConnection object at 0x104f77790>: Failed to establish a new connection: [Errno 61] Connection refused'))",
      "response_size": 0
    },
    {
      "timestamp": "2025-06-30 14:32:01.286514",
      "response_time": 0.003209352493286133,
      "status_code": 0,
      "success": false,
      "error_message": "HTTPConnectionPool(host='localhost', port=80): Max retries exceeded with url: /metrics (Caused by NewConnectionError('<urllib3.connection.HTTPConnection object at 0x104f76140>: Failed to establish a new connection: [Errno 61] Connection refused'))",
      "response_size": 0
    },
    {
      "timestamp": "2025-06-30 14:32:01.307154",
      "response_time": 0.0021333694458007812,
      "status_code": 0,
      "success": false,
      "error_message": "HTTPConnectionPool(host='localhost', port=80): Max retries exceeded with url: /api/ask (Caused by NewConnectionError('<urllib3.connection.HTTPConnection object at 0x104f75e10>: Failed to establish a new connection: [Errno 61] Connection refused'))",
      "response_size": 0
    },
    {
      "timestamp": "2025-06-30 14:32:01.470300",
      "response_time": 0.0014739036560058594,
      "status_code": 0,
      "success": false,
      "error_message": "HTTPConnectionPool(host='localhost', port=80): Max retries exceeded with url: /api/ask (Caused by NewConnectionError('<urllib3.connection.HTTPConnection object at 0x104f77130>: Failed to establish a new connection: [Errno 61] Connection refused'))",
      "response_size": 0
    },
    {
      "timestamp": "2025-06-30 14:32:01.472549",
      "response_time": 0.00150299072265625,
      "status_code": 0,
      "success": false,
      "error_message": "HTTPConnectionPool(host='localhost', port=80): Max retries exceeded with url: /api/ask (Caused by NewConnectionError('<urllib3.connection.HTTPConnection object at 0x104f769c0>: Failed to establish a new connection: [Errno 61] Connection refused'))",
      "response_size": 0
    },
    {
      "timestamp": "2025-06-30 14:32:01.472808",
      "response_time": 0.0012860298156738281,
      "status_code": 0,
      "success": false,
      "error_message": "HTTPConnectionPool(host='localhost', port=80): Max retries exceeded with url: /docs (Caused by NewConnectionError('<urllib3.connection.HTTPConnection object at 0x104f74e20>: Failed to establish a new connection: [Errno 61] Connection refused'))",
      "response_size": 0
    },
    {
      "timestamp": "2025-06-30 14:32:01.501251",
      "response_time": 0.002323150634765625,
      "status_code": 0,
      "success": false,
      "error_message": "HTTPConnectionPool(host='localhost', port=80): Max retries exceeded with url: /api/ask (Caused by NewConnectionError('<urllib3.connection.HTTPConnection object at 0x104f747c0>: Failed to establish a new connection: [Errno 61] Connection refused'))",
      "response_size": 0
    },
    {
      "timestamp": "2025-06-30 14:32:01.501804",
      "response_time": 0.0020110607147216797,
      "status_code": 0,
      "success": false,
      "error_message": "HTTPConnectionPool(host='localhost', port=80): Max retries exceeded with url: /docs (Caused by NewConnectionError('<urllib3.connection.HTTPConnection object at 0x104f74050>: Failed to establish a new connection: [Errno 61] Connection refused'))",
      "response_size": 0
    },
    {
      "timestamp": "2025-06-30 14:32:01.740776",
      "response_time": 0.0039098262786865234,
      "status_code": 0,
      "success": false,
      "error_message": "HTTPConnectionPool(host='localhost', port=80): Max retries exceeded with url: /health (Caused by NewConnectionError('<urllib3.connection.HTTPConnection object at 0x104f74d10>: Failed to establish a new connection: [Errno 61] Connection refused'))",
      "response_size": 0
    },
    {
      "timestamp": "2025-06-30 14:32:01.743194",
      "response_time": 0.0023958683013916016,
      "status_code": 0,
      "success": false,
      "error_message": "HTTPConnectionPool(host='localhost', port=80): Max retries exceeded with url: /api/ask (Caused by NewConnectionError('<urllib3.connection.HTTPConnection object at 0x104f75260>: Failed to establish a new connection: [Errno 61] Connection refused'))",
      "response_size": 0
    },
    {
      "timestamp": "2025-06-30 14:32:01.784595",
      "response_time": 0.0036551952362060547,
      "status_code": 0,
      "success": false,
      "error_message": "HTTPConnectionPool(host='localhost', port=80): Max retries exceeded with url: /api/ask (Caused by NewConnectionError('<urllib3.connection.HTTPConnection object at 0x104f76be0>: Failed to establish a new connection: [Errno 61] Connection refused'))",
      "response_size": 0
    },
    {
      "timestamp": "2025-06-30 14:32:01.786153",
      "response_time": 0.0026390552520751953,
      "status_code": 0,
      "success": false,
      "error_message": "HTTPConnectionPool(host='localhost', port=80): Max retries exceeded with url: /health (Caused by NewConnectionError('<urllib3.connection.HTTPConnection object at 0x104f758c0>: Failed to establish a new connection: [Errno 61] Connection refused'))",
      "response_size": 0
    },
    {
      "timestamp": "2025-06-30 14:32:01.794444",
      "response_time": 0.005079030990600586,
      "status_code": 0,
      "success": false,
      "error_message": "HTTPConnectionPool(host='localhost', port=80): Max retries exceeded with url: /metrics (Caused by NewConnectionError('<urllib3.connection.HTTPConnection object at 0x104f758c0>: Failed to establish a new connection: [Errno 61] Connection refused'))",
      "response_size": 0
    },
    {
      "timestamp": "2025-06-30 14:32:01.794721",
      "response_time": 0.004923820495605469,
      "status_code": 0,
      "success": false,
      "error_message": "HTTPConnectionPool(host='localhost', port=80): Max retries exceeded with url: /api/ask (Caused by NewConnectionError('<urllib3.connection.HTTPConnection object at 0x104f75590>: Failed to establish a new connection: [Errno 61] Connection refused'))",
      "response_size": 0
    },
    {
      "timestamp": "2025-06-30 14:32:01.794593",
      "response_time": 0.005231142044067383,
      "status_code": 0,
      "success": false,
      "error_message": "HTTPConnectionPool(host='localhost', port=80): Max retries exceeded with url: /api/ask (Caused by NewConnectionError('<urllib3.connection.HTTPConnection object at 0x104f76be0>: Failed to establish a new connection: [Errno 61] Connection refused'))",
      "response_size": 0
    },
    {
      "timestamp": "2025-06-30 14:32:01.814352",
      "response_time": 0.0023038387298583984,
      "status_code": 0,
      "success": false,
      "error_message": "HTTPConnectionPool(host='localhost', port=80): Max retries exceeded with url: /api/ask (Caused by NewConnectionError('<urllib3.connection.HTTPConnection object at 0x104f74d10>: Failed to establish a new connection: [Errno 61] Connection refused'))",
      "response_size": 0
    },
    {
      "timestamp": "2025-06-30 14:32:01.976874",
      "response_time": 0.005240917205810547,
      "status_code": 0,
      "success": false,
      "error_message": "HTTPConnectionPool(host='localhost', port=80): Max retries exceeded with url: /docs (Caused by NewConnectionError('<urllib3.connection.HTTPConnection object at 0x104f74050>: Failed to establish a new connection: [Errno 61] Connection refused'))",
      "response_size": 0
    },
    {
      "timestamp": "2025-06-30 14:32:01.979492",
      "response_time": 0.003075122833251953,
      "status_code": 0,
      "success": false,
      "error_message": "HTTPConnectionPool(host='localhost', port=80): Max retries exceeded with url: /api/ask (Caused by NewConnectionError('<urllib3.connection.HTTPConnection object at 0x104f778a0>: Failed to establish a new connection: [Errno 61] Connection refused'))",
      "response_size": 0
    },
    {
      "timestamp": "2025-06-30 14:32:01.979634",
      "response_time": 0.003263235092163086,
      "status_code": 0,
      "success": false,
      "error_message": "HTTPConnectionPool(host='localhost', port=80): Max retries exceeded with url: /api/ask (Caused by NewConnectionError('<urllib3.connection.HTTPConnection object at 0x104f747c0>: Failed to establish a new connection: [Errno 61] Connection refused'))",
      "response_size": 0
    },
    {
      "timestamp": "2025-06-30 14:32:02.005436",
      "response_time": 0.0035219192504882812,
      "status_code": 0,
      "success": false,
      "error_message": "HTTPConnectionPool(host='localhost', port=80): Max retries exceeded with url: /api/ask (Caused by NewConnectionError('<urllib3.connection.HTTPConnection object at 0x104f769c0>: Failed to establish a new connection: [Errno 61] Connection refused'))",
      "response_size": 0
    },
    {
      "timestamp": "2025-06-30 14:32:02.007422",
      "response_time": 0.002401113510131836,
      "status_code": 0,
      "success": false,
      "error_message": "HTTPConnectionPool(host='localhost', port=80): Max retries exceeded with url: /api/ask (Caused by NewConnectionError('<urllib3.connection.HTTPConnection object at 0x104f75150>: Failed to establish a new connection: [Errno 61] Connection refused'))",
      "response_size": 0
    },
    {
      "timestamp": "2025-06-30 14:32:02.249269",
      "response_time": 0.0035042762756347656,
      "status_code": 0,
      "success": false,
      "error_message": "HTTPConnectionPool(host='localhost', port=80): Max retries exceeded with url: /api/ask (Caused by NewConnectionError('<urllib3.connection.HTTPConnection object at 0x104f75e10>: Failed to establish a new connection: [Errno 61] Connection refused'))",
      "response_size": 0
    },
    {
      "timestamp": "2025-06-30 14:32:02.248950",
      "response_time": 0.003958940505981445,
      "status_code": 0,
      "success": false,
      "error_message": "HTTPConnectionPool(host='localhost', port=80): Max retries exceeded with url: /docs (Caused by NewConnectionError('<urllib3.connection.HTTPConnection object at 0x104f76e00>: Failed to establish a new connection: [Errno 61] Connection refused'))",
      "response_size": 0
    },
    {
      "timestamp": "2025-06-30 14:32:02.288486",
      "response_time": 0.003670930862426758,
      "status_code": 0,
      "success": false,
      "error_message": "HTTPConnectionPool(host='localhost', port=80): Max retries exceeded with url: /api/ask (Caused by NewConnectionError('<urllib3.connection.HTTPConnection object at 0x104f76690>: Failed to establish a new connection: [Errno 61] Connection refused'))",
      "response_size": 0
    },
    {
      "timestamp": "2025-06-30 14:32:02.290785",
      "response_time": 0.0021283626556396484,
      "status_code": 0,
      "success": false,
      "error_message": "HTTPConnectionPool(host='localhost', port=80): Max retries exceeded with url: /metrics (Caused by NewConnectionError('<urllib3.connection.HTTPConnection object at 0x104f77790>: Failed to establish a new connection: [Errno 61] Connection refused'))",
      "response_size": 0
    },
    {
      "timestamp": "2025-06-30 14:32:02.303405",
      "response_time": 0.0026738643646240234,
      "status_code": 0,
      "success": false,
      "error_message": "HTTPConnectionPool(host='localhost', port=80): Max retries exceeded with url: /health (Caused by NewConnectionError('<urllib3.connection.HTTPConnection object at 0x104f76250>: Failed to establish a new connection: [Errno 61] Connection refused'))",
      "response_size": 0
    },
    {
      "timestamp": "2025-06-30 14:32:02.303556",
      "response_time": 0.002780914306640625,
      "status_code": 0,
      "success": false,
      "error_message": "HTTPConnectionPool(host='localhost', port=80): Max retries exceeded with url: /api/ask (Caused by NewConnectionError('<urllib3.connection.HTTPConnection object at 0x104f77ac0>: Failed to establish a new connection: [Errno 61] Connection refused'))",
      "response_size": 0
    },
    {
      "timestamp": "2025-06-30 14:32:02.486006",
      "response_time": 0.0038259029388427734,
      "status_code": 0,
      "success": false,
      "error_message": "HTTPConnectionPool(host='localhost', port=80): Max retries exceeded with url: /metrics (Caused by NewConnectionError('<urllib3.connection.HTTPConnection object at 0x104f74160>: Failed to establish a new connection: [Errno 61] Connection refused'))",
      "response_size": 0
    },
    {
      "timestamp": "2025-06-30 14:32:02.485796",
      "response_time": 0.005817890167236328,
      "status_code": 0,
      "success": false,
      "error_message": "HTTPConnectionPool(host='localhost', port=80): Max retries exceeded with url: /docs (Caused by NewConnectionError('<urllib3.connection.HTTPConnection object at 0x104f77680>: Failed to establish a new connection: [Errno 61] Connection refused'))",
      "response_size": 0
    },
    {
      "timestamp": "2025-06-30 14:32:02.485451",
      "response_time": 0.00652003288269043,
      "status_code": 0,
      "success": false,
      "error_message": "HTTPConnectionPool(host='localhost', port=80): Max retries exceeded with url: /api/ask (Caused by NewConnectionError('<urllib3.connection.HTTPConnection object at 0x104f768b0>: Failed to establish a new connection: [Errno 61] Connection refused'))",
      "response_size": 0
    },
    {
      "timestamp": "2025-06-30 14:32:02.512940",
      "response_time": 0.0037949085235595703,
      "status_code": 0,
      "success": false,
      "error_message": "HTTPConnectionPool(host='localhost', port=80): Max retries exceeded with url: /api/ask (Caused by NewConnectionError('<urllib3.connection.HTTPConnection object at 0x104f75ae0>: Failed to establish a new connection: [Errno 61] Connection refused'))",
      "response_size": 0
    },
    {
      "timestamp": "2025-06-30 14:32:02.514330",
      "response_time": 0.002724885940551758,
      "status_code": 0,
      "success": false,
      "error_message": "HTTPConnectionPool(host='localhost', port=80): Max retries exceeded with url: /api/ask (Caused by NewConnectionError('<urllib3.connection.HTTPConnection object at 0x104f77ac0>: Failed to establish a new connection: [Errno 61] Connection refused'))",
      "response_size": 0
    },
    {
      "timestamp": "2025-06-30 14:32:02.753848",
      "response_time": 0.005057096481323242,
      "status_code": 0,
      "success": false,
      "error_message": "HTTPConnectionPool(host='localhost', port=80): Max retries exceeded with url: /api/ask (Caused by NewConnectionError('<urllib3.connection.HTTPConnection object at 0x104f75d00>: Failed to establish a new connection: [Errno 61] Connection refused'))",
      "response_size": 0
    },
    {
      "timestamp": "2025-06-30 14:32:02.753466",
      "response_time": 0.006412029266357422,
      "status_code": 0,
      "success": false,
      "error_message": "HTTPConnectionPool(host='localhost', port=80): Max retries exceeded with url: /api/ask (Caused by NewConnectionError('<urllib3.connection.HTTPConnection object at 0x104f77790>: Failed to establish a new connection: [Errno 61] Connection refused'))",
      "response_size": 0
    },
    {
      "timestamp": "2025-06-30 14:32:02.797995",
      "response_time": 0.0015900135040283203,
      "status_code": 0,
      "success": false,
      "error_message": "HTTPConnectionPool(host='localhost', port=80): Max retries exceeded with url: /api/ask (Caused by NewConnectionError('<urllib3.connection.HTTPConnection object at 0x104f75040>: Failed to establish a new connection: [Errno 61] Connection refused'))",
      "response_size": 0
    },
    {
      "timestamp": "2025-06-30 14:32:02.806564",
      "response_time": 0.0011057853698730469,
      "status_code": 0,
      "success": false,
      "error_message": "HTTPConnectionPool(host='localhost', port=80): Max retries exceeded with url: /api/ask (Caused by NewConnectionError('<urllib3.connection.HTTPConnection object at 0x104f76ad0>: Failed to establish a new connection: [Errno 61] Connection refused'))",
      "response_size": 0
    },
    {
      "timestamp": "2025-06-30 14:32:02.808768",
      "response_time": 0.0009860992431640625,
      "status_code": 0,
      "success": false,
      "error_message": "HTTPConnectionPool(host='localhost', port=80): Max retries exceeded with url: /docs (Caused by NewConnectionError('<urllib3.connection.HTTPConnection object at 0x104f76140>: Failed to establish a new connection: [Errno 61] Connection refused'))",
      "response_size": 0
    },
    {
      "timestamp": "2025-06-30 14:32:02.992546",
      "response_time": 0.004091978073120117,
      "status_code": 0,
      "success": false,
      "error_message": "HTTPConnectionPool(host='localhost', port=80): Max retries exceeded with url: /api/ask (Caused by NewConnectionError('<urllib3.connection.HTTPConnection object at 0x104f77570>: Failed to establish a new connection: [Errno 61] Connection refused'))",
      "response_size": 0
    },
    {
      "timestamp": "2025-06-30 14:32:02.992252",
      "response_time": 0.004742860794067383,
      "status_code": 0,
      "success": false,
      "error_message": "HTTPConnectionPool(host='localhost', port=80): Max retries exceeded with url: /api/ask (Caused by NewConnectionError('<urllib3.connection.HTTPConnection object at 0x104f769c0>: Failed to establish a new connection: [Errno 61] Connection refused'))",
      "response_size": 0
    },
    {
      "timestamp": "2025-06-30 14:32:03.017931",
      "response_time": 0.0038521289825439453,
      "status_code": 0,
      "success": false,
      "error_message": "HTTPConnectionPool(host='localhost', port=80): Max retries exceeded with url: /api/ask (Caused by NewConnectionError('<urllib3.connection.HTTPConnection object at 0x104f76030>: Failed to establish a new connection: [Errno 61] Connection refused'))",
      "response_size": 0
    },
    {
      "timestamp": "2025-06-30 14:32:03.020488",
      "response_time": 0.002663135528564453,
      "status_code": 0,
      "success": false,
      "error_message": "HTTPConnectionPool(host='localhost', port=80): Max retries exceeded with url: /metrics (Caused by NewConnectionError('<urllib3.connection.HTTPConnection object at 0x104f74e20>: Failed to establish a new connection: [Errno 61] Connection refused'))",
      "response_size": 0
    },
    {
      "timestamp": "2025-06-30 14:32:03.264016",
      "response_time": 0.004294872283935547,
      "status_code": 0,
      "success": false,
      "error_message": "HTTPConnectionPool(host='localhost', port=80): Max retries exceeded with url: /api/ask (Caused by NewConnectionError('<urllib3.connection.HTTPConnection object at 0x104f767a0>: Failed to establish a new connection: [Errno 61] Connection refused'))",
      "response_size": 0
    },
    {
      "timestamp": "2025-06-30 14:32:03.304650",
      "response_time": 0.0035398006439208984,
      "status_code": 0,
      "success": false,
      "error_message": "HTTPConnectionPool(host='localhost', port=80): Max retries exceeded with url: /docs (Caused by NewConnectionError('<urllib3.connection.HTTPConnection object at 0x104f75480>: Failed to establish a new connection: [Errno 61] Connection refused'))",
      "response_size": 0
    },
    {
      "timestamp": "2025-06-30 14:32:03.312723",
      "response_time": 0.0037767887115478516,
      "status_code": 0,
      "success": false,
      "error_message": "HTTPConnectionPool(host='localhost', port=80): Max retries exceeded with url: /metrics (Caused by NewConnectionError('<urllib3.connection.HTTPConnection object at 0x104f757b0>: Failed to establish a new connection: [Errno 61] Connection refused'))",
      "response_size": 0
    },
    {
      "timestamp": "2025-06-30 14:32:03.314809",
      "response_time": 0.002250194549560547,
      "status_code": 0,
      "success": false,
      "error_message": "HTTPConnectionPool(host='localhost', port=80): Max retries exceeded with url: /api/ask (Caused by NewConnectionError('<urllib3.connection.HTTPConnection object at 0x104f75590>: Failed to establish a new connection: [Errno 61] Connection refused'))",
      "response_size": 0
    },
    {
      "timestamp": "2025-06-30 14:32:03.500386",
      "response_time": 0.006569862365722656,
      "status_code": 0,
      "success": false,
      "error_message": "HTTPConnectionPool(host='localhost', port=80): Max retries exceeded with url: /health (Caused by NewConnectionError('<urllib3.connection.HTTPConnection object at 0x104f75590>: Failed to establish a new connection: [Errno 61] Connection refused'))",
      "response_size": 0
    },
    {
      "timestamp": "2025-06-30 14:32:03.501418",
      "response_time": 0.005741119384765625,
      "status_code": 0,
      "success": false,
      "error_message": "HTTPConnectionPool(host='localhost', port=80): Max retries exceeded with url: /api/ask (Caused by NewConnectionError('<urllib3.connection.HTTPConnection object at 0x104f758c0>: Failed to establish a new connection: [Errno 61] Connection refused'))",
      "response_size": 0
    },
    {
      "timestamp": "2025-06-30 14:32:03.525378",
      "response_time": 0.002146005630493164,
      "status_code": 0,
      "success": false,
      "error_message": "HTTPConnectionPool(host='localhost', port=80): Max retries exceeded with url: /health (Caused by NewConnectionError('<urllib3.connection.HTTPConnection object at 0x104f75480>: Failed to establish a new connection: [Errno 61] Connection refused'))",
      "response_size": 0
    },
    {
      "timestamp": "2025-06-30 14:32:03.771929",
      "response_time": 0.003857135772705078,
      "status_code": 0,
      "success": false,
      "error_message": "HTTPConnectionPool(host='localhost', port=80): Max retries exceeded with url: /api/ask (Caused by NewConnectionError('<urllib3.connection.HTTPConnection object at 0x104f767a0>: Failed to establish a new connection: [Errno 61] Connection refused'))",
      "response_size": 0
    },
    {
      "timestamp": "2025-06-30 14:32:03.810123",
      "response_time": 0.0035181045532226562,
      "status_code": 0,
      "success": false,
      "error_message": "HTTPConnectionPool(host='localhost', port=80): Max retries exceeded with url: /api/ask (Caused by NewConnectionError('<urllib3.connection.HTTPConnection object at 0x104f74e20>: Failed to establish a new connection: [Errno 61] Connection refused'))",
      "response_size": 0
    },
    {
      "timestamp": "2025-06-30 14:32:03.818218",
      "response_time": 0.0031778812408447266,
      "status_code": 0,
      "success": false,
      "error_message": "HTTPConnectionPool(host='localhost', port=80): Max retries exceeded with url: /health (Caused by NewConnectionError('<urllib3.connection.HTTPConnection object at 0x104f76030>: Failed to establish a new connection: [Errno 61] Connection refused'))",
      "response_size": 0
    },
    {
      "timestamp": "2025-06-30 14:32:03.818045",
      "response_time": 0.003919839859008789,
      "status_code": 0,
      "success": false,
      "error_message": "HTTPConnectionPool(host='localhost', port=80): Max retries exceeded with url: /api/ask (Caused by NewConnectionError('<urllib3.connection.HTTPConnection object at 0x104f778a0>: Failed to establish a new connection: [Errno 61] Connection refused'))",
      "response_size": 0
    },
    {
      "timestamp": "2025-06-30 14:32:04.011853",
      "response_time": 0.003847837448120117,
      "status_code": 0,
      "success": false,
      "error_message": "HTTPConnectionPool(host='localhost', port=80): Max retries exceeded with url: /health (Caused by NewConnectionError('<urllib3.connection.HTTPConnection object at 0x104f77570>: Failed to establish a new connection: [Errno 61] Connection refused'))",
      "response_size": 0
    },
    {
      "timestamp": "2025-06-30 14:32:04.032622",
      "response_time": 0.0038950443267822266,
      "status_code": 0,
      "success": false,
      "error_message": "HTTPConnectionPool(host='localhost', port=80): Max retries exceeded with url: /api/ask (Caused by NewConnectionError('<urllib3.connection.HTTPConnection object at 0x104f76140>: Failed to establish a new connection: [Errno 61] Connection refused'))",
      "response_size": 0
    },
    {
      "timestamp": "2025-06-30 14:32:04.278775",
      "response_time": 0.0045490264892578125,
      "status_code": 0,
      "success": false,
      "error_message": "HTTPConnectionPool(host='localhost', port=80): Max retries exceeded with url: /api/ask (Caused by NewConnectionError('<urllib3.connection.HTTPConnection object at 0x104f76ad0>: Failed to establish a new connection: [Errno 61] Connection refused'))",
      "response_size": 0
    },
    {
      "timestamp": "2025-06-30 14:32:04.317976",
      "response_time": 0.004104137420654297,
      "status_code": 0,
      "success": false,
      "error_message": "HTTPConnectionPool(host='localhost', port=80): Max retries exceeded with url: /docs (Caused by NewConnectionError('<urllib3.connection.HTTPConnection object at 0x104f75040>: Failed to establish a new connection: [Errno 61] Connection refused'))",
      "response_size": 0
    },
    {
      "timestamp": "2025-06-30 14:32:04.324149",
      "response_time": 0.002650022506713867,
      "status_code": 0,
      "success": false,
      "error_message": "HTTPConnectionPool(host='localhost', port=80): Max retries exceeded with url: /api/ask (Caused by NewConnectionError('<urllib3.connection.HTTPConnection object at 0x104f77790>: Failed to establish a new connection: [Errno 61] Connection refused'))",
      "response_size": 0
    },
    {
      "timestamp": "2025-06-30 14:32:04.536968",
      "response_time": 0.004333019256591797,
      "status_code": 0,
      "success": false,
      "error_message": "HTTPConnectionPool(host='localhost', port=80): Max retries exceeded with url: /api/ask (Caused by NewConnectionError('<urllib3.connection.HTTPConnection object at 0x104f75d00>: Failed to establish a new connection: [Errno 61] Connection refused'))",
      "response_size": 0
    },
    {
      "timestamp": "2025-06-30 14:32:04.784635",
      "response_time": 0.0038199424743652344,
      "status_code": 0,
      "success": false,
      "error_message": "HTTPConnectionPool(host='localhost', port=80): Max retries exceeded with url: /docs (Caused by NewConnectionError('<urllib3.connection.HTTPConnection object at 0x104f77ac0>: Failed to establish a new connection: [Errno 61] Connection refused'))",
      "response_size": 0
    },
    {
      "timestamp": "2025-06-30 14:32:04.831917",
      "response_time": 0.0015521049499511719,
      "status_code": 0,
      "success": false,
      "error_message": "HTTPConnectionPool(host='localhost', port=80): Max retries exceeded with url: /api/ask (Caused by NewConnectionError('<urllib3.connection.HTTPConnection object at 0x104f75ae0>: Failed to establish a new connection: [Errno 61] Connection refused'))",
      "response_size": 0
    },
    {
      "timestamp": "2025-06-30 14:32:05.338552",
      "response_time": 0.0038771629333496094,
      "status_code": 0,
      "success": false,
      "error_message": "HTTPConnectionPool(host='localhost', port=80): Max retries exceeded with url: /api/ask (Caused by NewConnectionError('<urllib3.connection.HTTPConnection object at 0x104f768b0>: Failed to establish a new connection: [Errno 61] Connection refused'))",
      "response_size": 0
    }
  ]
}