{
  "test_timestamp": "20250630_143107",
  "test_config": {
    "base_url": "http://localhost",
    "port": 80,
    "num_concurrent_users": 50,
    "num_requests_per_user": 100,
    "ramp_up_time": 60,
    "test_duration": 300,
    "request_timeout": 30,
    "think_time": 0.5
  },
  "results": {
    "total_requests": 5000,
    "successful_requests": 0,
    "failed_requests": 5000,
    "average_response_time": 0.004766906881332397,
    "median_response_time": 0.0038090944290161133,
    "p95_response_time": 0.010213029384613038,
    "p99_response_time": 0.015497214794158935,
    "min_response_time": 0.0004918575286865234,
    "max_response_time": 0.0771169662475586,
    "requests_per_second": 45.7425216580548,
    "error_rate": 100.0,
    "test_duration": 109.307485,
    "concurrent_users": 50
  },
  "detailed_results": [
    {
      "timestamp": "2025-06-30 14:30:57.787990",
      "response_time": 0.005639314651489258,
      "status_code": 0,
      "success": false,
      "error_message": "HTTPConnectionPool(host='localhost', port=80): Max retries exceeded with url: /api/ask (Caused by NewConnectionError('<urllib3.connection.HTTPConnection object at 0x104e9a360>: Failed to establish a new connection: [Errno 61] Connection refused'))",
      "response_size": 0
    },
    {
      "timestamp": "2025-06-30 14:30:57.788994",
      "response_time": 0.004750728607177734,
      "status_code": 0,
      "success": false,
      "error_message": "HTTPConnectionPool(host='localhost', port=80): Max retries exceeded with url: /api/ask (Caused by NewConnectionError('<urllib3.connection.HTTPConnection object at 0x104e9bce0>: Failed to establish a new connection: [Errno 61] Connection refused'))",
      "response_size": 0
    },
    {
      "timestamp": "2025-06-30 14:30:57.788293",
      "response_time": 0.005544900894165039,
      "status_code": 0,
      "success": false,
      "error_message": "HTTPConnectionPool(host='localhost', port=80): Max retries exceeded with url: /api/ask (Caused by NewConnectionError('<urllib3.connection.HTTPConnection object at 0x104e9ae00>: Failed to establish a new connection: [Errno 61] Connection refused'))",
      "response_size": 0
    },
    {
      "timestamp": "2025-06-30 14:30:57.943275",
      "response_time": 0.007863759994506836,
      "status_code": 0,
      "success": false,
      "error_message": "HTTPConnectionPool(host='localhost', port=80): Max retries exceeded with url: /api/ask (Caused by NewConnectionError('<urllib3.connection.HTTPConnection object at 0x104e9ae00>: Failed to establish a new connection: [Errno 61] Connection refused'))",
      "response_size": 0
    },
    {
      "timestamp": "2025-06-30 14:30:57.947747",
      "response_time": 0.004158973693847656,
      "status_code": 0,
      "success": false,
      "error_message": "HTTPConnectionPool(host='localhost', port=80): Max retries exceeded with url: /api/ask (Caused by NewConnectionError('<urllib3.connection.HTTPConnection object at 0x104e9bce0>: Failed to establish a new connection: [Errno 61] Connection refused'))",
      "response_size": 0
    },
    {
      "timestamp": "2025-06-30 14:30:57.948226",
      "response_time": 0.004179954528808594,
      "status_code": 0,
      "success": false,
      "error_message": "HTTPConnectionPool(host='localhost', port=80): Max retries exceeded with url: /docs (Caused by NewConnectionError('<urllib3.connection.HTTPConnection object at 0x104e9a360>: Failed to establish a new connection: [Errno 61] Connection refused'))",
      "response_size": 0
    },
    {
      "timestamp": "2025-06-30 14:30:57.945163",
      "response_time": 0.007341146469116211,
      "status_code": 0,
      "success": false,
      "error_message": "HTTPConnectionPool(host='localhost', port=80): Max retries exceeded with url: /health (Caused by NewConnectionError('<urllib3.connection.HTTPConnection object at 0x104e9b790>: Failed to establish a new connection: [Errno 61] Connection refused'))",
      "response_size": 0
    },
    {
      "timestamp": "2025-06-30 14:30:58.021516",
      "response_time": 0.002496957778930664,
      "status_code": 0,
      "success": false,
      "error_message": "HTTPConnectionPool(host='localhost', port=80): Max retries exceeded with url: /metrics (Caused by NewConnectionError('<urllib3.connection.HTTPConnection object at 0x104e9b130>: Failed to establish a new connection: [Errno 61] Connection refused'))",
      "response_size": 0
    },
    {
      "timestamp": "2025-06-30 14:30:58.293863",
      "response_time": 0.004745960235595703,
      "status_code": 0,
      "success": false,
      "error_message": "HTTPConnectionPool(host='localhost', port=80): Max retries exceeded with url: /api/ask (Caused by NewConnectionError('<urllib3.connection.HTTPConnection object at 0x104e9a580>: Failed to establish a new connection: [Errno 61] Connection refused'))",
      "response_size": 0
    },
    {
      "timestamp": "2025-06-30 14:30:58.296937",
      "response_time": 0.0033919811248779297,
      "status_code": 0,
      "success": false,
      "error_message": "HTTPConnectionPool(host='localhost', port=80): Max retries exceeded with url: /health (Caused by NewConnectionError('<urllib3.connection.HTTPConnection object at 0x104e9bac0>: Failed to establish a new connection: [Errno 61] Connection refused'))",
      "response_size": 0
    },
    {
      "timestamp": "2025-06-30 14:30:58.297357",
      "response_time": 0.0031359195709228516,
      "status_code": 0,
      "success": false,
      "error_message": "HTTPConnectionPool(host='localhost', port=80): Max retries exceeded with url: /api/ask (Caused by NewConnectionError('<urllib3.connection.HTTPConnection object at 0x104e9a7a0>: Failed to establish a new connection: [Errno 61] Connection refused'))",
      "response_size": 0
    },
    {
      "timestamp": "2025-06-30 14:30:58.298934",
      "response_time": 0.002273082733154297,
      "status_code": 0,
      "success": false,
      "error_message": "HTTPConnectionPool(host='localhost', port=80): Max retries exceeded with url: /api/ask (Caused by NewConnectionError('<urllib3.connection.HTTPConnection object at 0x104e9b240>: Failed to establish a new connection: [Errno 61] Connection refused'))",
      "response_size": 0
    },
    {
      "timestamp": "2025-06-30 14:30:58.452151",
      "response_time": 0.0058062076568603516,
      "status_code": 0,
      "success": false,
      "error_message": "HTTPConnectionPool(host='localhost', port=80): Max retries exceeded with url: /api/ask (Caused by NewConnectionError('<urllib3.connection.HTTPConnection object at 0x104e9b460>: Failed to establish a new connection: [Errno 61] Connection refused'))",
      "response_size": 0
    },
    {
      "timestamp": "2025-06-30 14:30:58.455169",
      "response_time": 0.003712177276611328,
      "status_code": 0,
      "success": false,
      "error_message": "HTTPConnectionPool(host='localhost', port=80): Max retries exceeded with url: /api/ask (Caused by NewConnectionError('<urllib3.connection.HTTPConnection object at 0x104e9a470>: Failed to establish a new connection: [Errno 61] Connection refused'))",
      "response_size": 0
    },
    {
      "timestamp": "2025-06-30 14:30:58.455439",
      "response_time": 0.003573894500732422,
      "status_code": 0,
      "success": false,
      "error_message": "HTTPConnectionPool(host='localhost', port=80): Max retries exceeded with url: /api/ask (Caused by NewConnectionError('<urllib3.connection.HTTPConnection object at 0x104e9bf00>: Failed to establish a new connection: [Errno 61] Connection refused'))",
      "response_size": 0
    },
    {
      "timestamp": "2025-06-30 14:30:58.457430",
      "response_time": 0.002173900604248047,
      "status_code": 0,
      "success": false,
      "error_message": "HTTPConnectionPool(host='localhost', port=80): Max retries exceeded with url: /api/ask (Caused by NewConnectionError('<urllib3.connection.HTTPConnection object at 0x104e99260>: Failed to establish a new connection: [Errno 61] Connection refused'))",
      "response_size": 0
    },
    {
      "timestamp": "2025-06-30 14:30:58.528057",
      "response_time": 0.003280162811279297,
      "status_code": 0,
      "success": false,
      "error_message": "HTTPConnectionPool(host='localhost', port=80): Max retries exceeded with url: /api/ask (Caused by NewConnectionError('<urllib3.connection.HTTPConnection object at 0x104e9b020>: Failed to establish a new connection: [Errno 61] Connection refused'))",
      "response_size": 0
    },
    {
      "timestamp": "2025-06-30 14:30:58.804587",
      "response_time": 0.004027128219604492,
      "status_code": 0,
      "success": false,
      "error_message": "HTTPConnectionPool(host='localhost', port=80): Max retries exceeded with url: /api/ask (Caused by NewConnectionError('<urllib3.connection.HTTPConnection object at 0x104e9a140>: Failed to establish a new connection: [Errno 61] Connection refused'))",
      "response_size": 0
    },
    {
      "timestamp": "2025-06-30 14:30:58.803319",
      "response_time": 0.0054779052734375,
      "status_code": 0,
      "success": false,
      "error_message": "HTTPConnectionPool(host='localhost', port=80): Max retries exceeded with url: /health (Caused by NewConnectionError('<urllib3.connection.HTTPConnection object at 0x104e9bbd0>: Failed to establish a new connection: [Errno 61] Connection refused'))",
      "response_size": 0
    },
    {
      "timestamp": "2025-06-30 14:30:58.804352",
      "response_time": 0.004558086395263672,
      "status_code": 0,
      "success": false,
      "error_message": "HTTPConnectionPool(host='localhost', port=80): Max retries exceeded with url: /health (Caused by NewConnectionError('<urllib3.connection.HTTPConnection object at 0x104f74af0>: Failed to establish a new connection: [Errno 61] Connection refused'))",
      "response_size": 0
    },
    {
      "timestamp": "2025-06-30 14:30:58.963439",
      "response_time": 0.0053730010986328125,
      "status_code": 0,
      "success": false,
      "error_message": "HTTPConnectionPool(host='localhost', port=80): Max retries exceeded with url: /api/ask (Caused by NewConnectionError('<urllib3.connection.HTTPConnection object at 0x104e9bbd0>: Failed to establish a new connection: [Errno 61] Connection refused'))",
      "response_size": 0
    },
    {
      "timestamp": "2025-06-30 14:30:58.963268",
      "response_time": 0.005958080291748047,
      "status_code": 0,
      "success": false,
      "error_message": "HTTPConnectionPool(host='localhost', port=80): Max retries exceeded with url: /api/ask (Caused by NewConnectionError('<urllib3.connection.HTTPConnection object at 0x104e9a140>: Failed to establish a new connection: [Errno 61] Connection refused'))",
      "response_size": 0
    },
    {
      "timestamp": "2025-06-30 14:30:58.964797",
      "response_time": 0.004821062088012695,
      "status_code": 0,
      "success": false,
      "error_message": "HTTPConnectionPool(host='localhost', port=80): Max retries exceeded with url: /api/ask (Caused by NewConnectionError('<urllib3.connection.HTTPConnection object at 0x104e99f20>: Failed to establish a new connection: [Errno 61] Connection refused'))",
      "response_size": 0
    },
    {
      "timestamp": "2025-06-30 14:30:58.960153",
      "response_time": 0.009560108184814453,
      "status_code": 0,
      "success": false,
      "error_message": "HTTPConnectionPool(host='localhost', port=80): Max retries exceeded with url: /metrics (Caused by NewConnectionError('<urllib3.connection.HTTPConnection object at 0x104e9b020>: Failed to establish a new connection: [Errno 61] Connection refused'))",
      "response_size": 0
    },
    {
      "timestamp": "2025-06-30 14:30:59.035467",
      "response_time": 0.003589153289794922,
      "status_code": 0,
      "success": false,
      "error_message": "HTTPConnectionPool(host='localhost', port=80): Max retries exceeded with url: /api/ask (Caused by NewConnectionError('<urllib3.connection.HTTPConnection object at 0x104e9a470>: Failed to establish a new connection: [Errno 61] Connection refused'))",
      "response_size": 0
    },
    {
      "timestamp": "2025-06-30 14:30:59.309620",
      "response_time": 0.004488945007324219,
      "status_code": 0,
      "success": false,
      "error_message": "HTTPConnectionPool(host='localhost', port=80): Max retries exceeded with url: /metrics (Caused by NewConnectionError('<urllib3.connection.HTTPConnection object at 0x104e9b460>: Failed to establish a new connection: [Errno 61] Connection refused'))",
      "response_size": 0
    },
    {
      "timestamp": "2025-06-30 14:30:59.312072",
      "response_time": 0.002528667449951172,
      "status_code": 0,
      "success": false,
      "error_message": "HTTPConnectionPool(host='localhost', port=80): Max retries exceeded with url: /api/ask (Caused by NewConnectionError('<urllib3.connection.HTTPConnection object at 0x104e98e20>: Failed to establish a new connection: [Errno 61] Connection refused'))",
      "response_size": 0
    },
    {
      "timestamp": "2025-06-30 14:30:59.312397",
      "response_time": 0.0023040771484375,
      "status_code": 0,
      "success": false,
      "error_message": "HTTPConnectionPool(host='localhost', port=80): Max retries exceeded with url: /api/ask (Caused by NewConnectionError('<urllib3.connection.HTTPConnection object at 0x104e9b240>: Failed to establish a new connection: [Errno 61] Connection refused'))",
      "response_size": 0
    },
    {
      "timestamp": "2025-06-30 14:30:59.469449",
      "response_time": 0.0046389102935791016,
      "status_code": 0,
      "success": false,
      "error_message": "HTTPConnectionPool(host='localhost', port=80): Max retries exceeded with url: /api/ask (Caused by NewConnectionError('<urllib3.connection.HTTPConnection object at 0x104e9bac0>: Failed to establish a new connection: [Errno 61] Connection refused'))",
      "response_size": 0
    },
    {
      "timestamp": "2025-06-30 14:30:59.472894",
      "response_time": 0.00411534309387207,
      "status_code": 0,
      "success": false,
      "error_message": "HTTPConnectionPool(host='localhost', port=80): Max retries exceeded with url: /health (Caused by NewConnectionError('<urllib3.connection.HTTPConnection object at 0x104e9a580>: Failed to establish a new connection: [Errno 61] Connection refused'))",
      "response_size": 0
    },
    {
      "timestamp": "2025-06-30 14:30:59.474842",
      "response_time": 0.0026068687438964844,
      "status_code": 0,
      "success": false,
      "error_message": "HTTPConnectionPool(host='localhost', port=80): Max retries exceeded with url: /api/ask (Caused by NewConnectionError('<urllib3.connection.HTTPConnection object at 0x104e9b8a0>: Failed to establish a new connection: [Errno 61] Connection refused'))",
      "response_size": 0
    },
    {
      "timestamp": "2025-06-30 14:30:59.474724",
      "response_time": 0.0030646324157714844,
      "status_code": 0,
      "success": false,
      "error_message": "HTTPConnectionPool(host='localhost', port=80): Max retries exceeded with url: /api/ask (Caused by NewConnectionError('<urllib3.connection.HTTPConnection object at 0x104e9b130>: Failed to establish a new connection: [Errno 61] Connection refused'))",
      "response_size": 0
    },
    {
      "timestamp": "2025-06-30 14:30:59.544115",
      "response_time": 0.0031881332397460938,
      "status_code": 0,
      "success": false,
      "error_message": "HTTPConnectionPool(host='localhost', port=80): Max retries exceeded with url: /api/ask (Caused by NewConnectionError('<urllib3.connection.HTTPConnection object at 0x104e9a360>: Failed to establish a new connection: [Errno 61] Connection refused'))",
      "response_size": 0
    },
    {
      "timestamp": "2025-06-30 14:30:59.817653",
      "response_time": 0.005422830581665039,
      "status_code": 0,
      "success": false,
      "error_message": "HTTPConnectionPool(host='localhost', port=80): Max retries exceeded with url: /api/ask (Caused by NewConnectionError('<urllib3.connection.HTTPConnection object at 0x104e9bce0>: Failed to establish a new connection: [Errno 61] Connection refused'))",
      "response_size": 0
    },
    {
      "timestamp": "2025-06-30 14:30:59.819176",
      "response_time": 0.00405120849609375,
      "status_code": 0,
      "success": false,
      "error_message": "HTTPConnectionPool(host='localhost', port=80): Max retries exceeded with url: /api/ask (Caused by NewConnectionError('<urllib3.connection.HTTPConnection object at 0x104e99370>: Failed to establish a new connection: [Errno 61] Connection refused'))",
      "response_size": 0
    },
    {
      "timestamp": "2025-06-30 14:30:59.820089",
      "response_time": 0.0036208629608154297,
      "status_code": 0,
      "success": false,
      "error_message": "HTTPConnectionPool(host='localhost', port=80): Max retries exceeded with url: /api/ask (Caused by NewConnectionError('<urllib3.connection.HTTPConnection object at 0x104e9ae00>: Failed to establish a new connection: [Errno 61] Connection refused'))",
      "response_size": 0
    },
    {
      "timestamp": "2025-06-30 14:30:59.983682",
      "response_time": 0.0020952224731445312,
      "status_code": 0,
      "success": false,
      "error_message": "HTTPConnectionPool(host='localhost', port=80): Max retries exceeded with url: /api/ask (Caused by NewConnectionError('<urllib3.connection.HTTPConnection object at 0x104e9bce0>: Failed to establish a new connection: [Errno 61] Connection refused'))",
      "response_size": 0
    },
    {
      "timestamp": "2025-06-30 14:30:59.982258",
      "response_time": 0.003576040267944336,
      "status_code": 0,
      "success": false,
      "error_message": "HTTPConnectionPool(host='localhost', port=80): Max retries exceeded with url: /api/ask (Caused by NewConnectionError('<urllib3.connection.HTTPConnection object at 0x104e9ae00>: Failed to establish a new connection: [Errno 61] Connection refused'))",
      "response_size": 0
    },
    {
      "timestamp": "2025-06-30 14:30:59.982109",
      "response_time": 0.0037648677825927734,
      "status_code": 0,
      "success": false,
      "error_message": "HTTPConnectionPool(host='localhost', port=80): Max retries exceeded with url: /api/ask (Caused by NewConnectionError('<urllib3.connection.HTTPConnection object at 0x104e99370>: Failed to establish a new connection: [Errno 61] Connection refused'))",
      "response_size": 0
    },
    {
      "timestamp": "2025-06-30 14:31:00.050926",
      "response_time": 0.003341197967529297,
      "status_code": 0,
      "success": false,
      "error_message": "HTTPConnectionPool(host='localhost', port=80): Max retries exceeded with url: /api/ask (Caused by NewConnectionError('<urllib3.connection.HTTPConnection object at 0x104e9b130>: Failed to establish a new connection: [Errno 61] Connection refused'))",
      "response_size": 0
    },
    {
      "timestamp": "2025-06-30 14:31:00.325849",
      "response_time": 0.004014253616333008,
      "status_code": 0,
      "success": false,
      "error_message": "HTTPConnectionPool(host='localhost', port=80): Max retries exceeded with url: /docs (Caused by NewConnectionError('<urllib3.connection.HTTPConnection object at 0x104e9b8a0>: Failed to establish a new connection: [Errno 61] Connection refused'))",
      "response_size": 0
    },
    {
      "timestamp": "2025-06-30 14:31:00.327969",
      "response_time": 0.0022161006927490234,
      "status_code": 0,
      "success": false,
      "error_message": "HTTPConnectionPool(host='localhost', port=80): Max retries exceeded with url: /docs (Caused by NewConnectionError('<urllib3.connection.HTTPConnection object at 0x104e9b790>: Failed to establish a new connection: [Errno 61] Connection refused'))",
      "response_size": 0
    },
    {
      "timestamp": "2025-06-30 14:31:00.327810",
      "response_time": 0.002438068389892578,
      "status_code": 0,
      "success": false,
      "error_message": "HTTPConnectionPool(host='localhost', port=80): Max retries exceeded with url: /metrics (Caused by NewConnectionError('<urllib3.connection.HTTPConnection object at 0x104e9a580>: Failed to establish a new connection: [Errno 61] Connection refused'))",
      "response_size": 0
    },
    {
      "timestamp": "2025-06-30 14:31:00.491761",
      "response_time": 0.0033960342407226562,
      "status_code": 0,
      "success": false,
      "error_message": "HTTPConnectionPool(host='localhost', port=80): Max retries exceeded with url: /api/ask (Caused by NewConnectionError('<urllib3.connection.HTTPConnection object at 0x104e9b240>: Failed to establish a new connection: [Errno 61] Connection refused'))",
      "response_size": 0
    },
    {
      "timestamp": "2025-06-30 14:31:00.491114",
      "response_time": 0.004143953323364258,
      "status_code": 0,
      "success": false,
      "error_message": "HTTPConnectionPool(host='localhost', port=80): Max retries exceeded with url: /health (Caused by NewConnectionError('<urllib3.connection.HTTPConnection object at 0x104e9b350>: Failed to establish a new connection: [Errno 61] Connection refused'))",
      "response_size": 0
    },
    {
      "timestamp": "2025-06-30 14:31:00.490857",
      "response_time": 0.004478931427001953,
      "status_code": 0,
      "success": false,
      "error_message": "HTTPConnectionPool(host='localhost', port=80): Max retries exceeded with url: /api/ask (Caused by NewConnectionError('<urllib3.connection.HTTPConnection object at 0x104e9b570>: Failed to establish a new connection: [Errno 61] Connection refused'))",
      "response_size": 0
    },
    {
      "timestamp": "2025-06-30 14:31:00.559345",
      "response_time": 0.002974987030029297,
      "status_code": 0,
      "success": false,
      "error_message": "HTTPConnectionPool(host='localhost', port=80): Max retries exceeded with url: /api/ask (Caused by NewConnectionError('<urllib3.connection.HTTPConnection object at 0x104e9b9b0>: Failed to establish a new connection: [Errno 61] Connection refused'))",
      "response_size": 0
    },
    {
      "timestamp": "2025-06-30 14:31:00.831123",
      "response_time": 0.003971099853515625,
      "status_code": 0,
      "success": false,
      "error_message": "HTTPConnectionPool(host='localhost', port=80): Max retries exceeded with url: /api/ask (Caused by NewConnectionError('<urllib3.connection.HTTPConnection object at 0x104e9aad0>: Failed to establish a new connection: [Errno 61] Connection refused'))",
      "response_size": 0
    },
    {
      "timestamp": "2025-06-30 14:31:00.830672",
      "response_time": 0.005374908447265625,
      "status_code": 0,
      "success": false,
      "error_message": "HTTPConnectionPool(host='localhost', port=80): Max retries exceeded with url: /api/ask (Caused by NewConnectionError('<urllib3.connection.HTTPConnection object at 0x104e9b020>: Failed to establish a new connection: [Errno 61] Connection refused'))",
      "response_size": 0
    },
    {
      "timestamp": "2025-06-30 14:31:00.835288",
      "response_time": 0.003019094467163086,
      "status_code": 0,
      "success": false,
      "error_message": "HTTPConnectionPool(host='localhost', port=80): Max retries exceeded with url: /metrics (Caused by NewConnectionError('<urllib3.connection.HTTPConnection object at 0x104e9bf00>: Failed to establish a new connection: [Errno 61] Connection refused'))",
      "response_size": 0
    },
    {
      "timestamp": "2025-06-30 14:31:01.000880",
      "response_time": 0.004314899444580078,
      "status_code": 0,
      "success": false,
      "error_message": "HTTPConnectionPool(host='localhost', port=80): Max retries exceeded with url: /metrics (Caused by NewConnectionError('<urllib3.connection.HTTPConnection object at 0x104e9bbd0>: Failed to establish a new connection: [Errno 61] Connection refused'))",
      "response_size": 0
    },
    {
      "timestamp": "2025-06-30 14:31:01.000279",
      "response_time": 0.006506204605102539,
      "status_code": 0,
      "success": false,
      "error_message": "HTTPConnectionPool(host='localhost', port=80): Max retries exceeded with url: /docs (Caused by NewConnectionError('<urllib3.connection.HTTPConnection object at 0x104e9a9c0>: Failed to establish a new connection: [Errno 61] Connection refused'))",
      "response_size": 0
    },
    {
      "timestamp": "2025-06-30 14:31:01.000661",
      "response_time": 0.0065190792083740234,
      "status_code": 0,
      "success": false,
      "error_message": "HTTPConnectionPool(host='localhost', port=80): Max retries exceeded with url: /api/ask (Caused by NewConnectionError('<urllib3.connection.HTTPConnection object at 0x104e99260>: Failed to establish a new connection: [Errno 61] Connection refused'))",
      "response_size": 0
    },
    {
      "timestamp": "2025-06-30 14:31:01.067441",
      "response_time": 0.0032019615173339844,
      "status_code": 0,
      "success": false,
      "error_message": "HTTPConnectionPool(host='localhost', port=80): Max retries exceeded with url: /api/ask (Caused by NewConnectionError('<urllib3.connection.HTTPConnection object at 0x104e9bf00>: Failed to establish a new connection: [Errno 61] Connection refused'))",
      "response_size": 0
    },
    {
      "timestamp": "2025-06-30 14:31:01.340241",
      "response_time": 0.0050890445709228516,
      "status_code": 0,
      "success": false,
      "error_message": "HTTPConnectionPool(host='localhost', port=80): Max retries exceeded with url: /api/ask (Caused by NewConnectionError('<urllib3.connection.HTTPConnection object at 0x104e9b020>: Failed to establish a new connection: [Errno 61] Connection refused'))",
      "response_size": 0
    },
    {
      "timestamp": "2025-06-30 14:31:01.343535",
      "response_time": 0.00267791748046875,
      "status_code": 0,
      "success": false,
      "error_message": "HTTPConnectionPool(host='localhost', port=80): Max retries exceeded with url: /health (Caused by NewConnectionError('<urllib3.connection.HTTPConnection object at 0x104e99f20>: Failed to establish a new connection: [Errno 61] Connection refused'))",
      "response_size": 0
    },
    {
      "timestamp": "2025-06-30 14:31:01.506502",
      "response_time": 0.004336118698120117,
      "status_code": 0,
      "success": false,
      "error_message": "HTTPConnectionPool(host='localhost', port=80): Max retries exceeded with url: /api/ask (Caused by NewConnectionError('<urllib3.connection.HTTPConnection object at 0x104e9b9b0>: Failed to establish a new connection: [Errno 61] Connection refused'))",
      "response_size": 0
    },
    {
      "timestamp": "2025-06-30 14:31:01.509486",
      "response_time": 0.002827882766723633,
      "status_code": 0,
      "success": false,
      "error_message": "HTTPConnectionPool(host='localhost', port=80): Max retries exceeded with url: /api/ask (Caused by NewConnectionError('<urllib3.connection.HTTPConnection object at 0x104e9b570>: Failed to establish a new connection: [Errno 61] Connection refused'))",
      "response_size": 0
    },
    {
      "timestamp": "2025-06-30 14:31:01.511876",
      "response_time": 0.001965761184692383,
      "status_code": 0,
      "success": false,
      "error_message": "HTTPConnectionPool(host='localhost', port=80): Max retries exceeded with url: /health (Caused by NewConnectionError('<urllib3.connection.HTTPConnection object at 0x104e9b350>: Failed to establish a new connection: [Errno 61] Connection refused'))",
      "response_size": 0
    },
    {
      "timestamp": "2025-06-30 14:31:01.572765",
      "response_time": 0.003659963607788086,
      "status_code": 0,
      "success": false,
      "error_message": "HTTPConnectionPool(host='localhost', port=80): Max retries exceeded with url: /docs (Caused by NewConnectionError('<urllib3.connection.HTTPConnection object at 0x104e9b240>: Failed to establish a new connection: [Errno 61] Connection refused'))",
      "response_size": 0
    },
    {
      "timestamp": "2025-06-30 14:31:01.848787",
      "response_time": 0.004275798797607422,
      "status_code": 0,
      "success": false,
      "error_message": "HTTPConnectionPool(host='localhost', port=80): Max retries exceeded with url: /api/ask (Caused by NewConnectionError('<urllib3.connection.HTTPConnection object at 0x104e9a580>: Failed to establish a new connection: [Errno 61] Connection refused'))",
      "response_size": 0
    },
    {
      "timestamp": "2025-06-30 14:31:01.850392",
      "response_time": 0.002789020538330078,
      "status_code": 0,
      "success": false,
      "error_message": "HTTPConnectionPool(host='localhost', port=80): Max retries exceeded with url: /api/ask (Caused by NewConnectionError('<urllib3.connection.HTTPConnection object at 0x104e9bac0>: Failed to establish a new connection: [Errno 61] Connection refused'))",
      "response_size": 0
    },
    {
      "timestamp": "2025-06-30 14:31:02.014399",
      "response_time": 0.004518270492553711,
      "status_code": 0,
      "success": false,
      "error_message": "HTTPConnectionPool(host='localhost', port=80): Max retries exceeded with url: /api/ask (Caused by NewConnectionError('<urllib3.connection.HTTPConnection object at 0x104e9b8a0>: Failed to establish a new connection: [Errno 61] Connection refused'))",
      "response_size": 0
    },
    {
      "timestamp": "2025-06-30 14:31:02.014021",
      "response_time": 0.0050470829010009766,
      "status_code": 0,
      "success": false,
      "error_message": "HTTPConnectionPool(host='localhost', port=80): Max retries exceeded with url: /api/ask (Caused by NewConnectionError('<urllib3.connection.HTTPConnection object at 0x104e99150>: Failed to establish a new connection: [Errno 61] Connection refused'))",
      "response_size": 0
    },
    {
      "timestamp": "2025-06-30 14:31:02.017143",
      "response_time": 0.002876758575439453,
      "status_code": 0,
      "success": false,
      "error_message": "HTTPConnectionPool(host='localhost', port=80): Max retries exceeded with url: /health (Caused by NewConnectionError('<urllib3.connection.HTTPConnection object at 0x104e9b130>: Failed to establish a new connection: [Errno 61] Connection refused'))",
      "response_size": 0
    },
    {
      "timestamp": "2025-06-30 14:31:02.080650",
      "response_time": 0.0036339759826660156,
      "status_code": 0,
      "success": false,
      "error_message": "HTTPConnectionPool(host='localhost', port=80): Max retries exceeded with url: /api/ask (Caused by NewConnectionError('<urllib3.connection.HTTPConnection object at 0x104e9ae00>: Failed to establish a new connection: [Errno 61] Connection refused'))",
      "response_size": 0
    },
    {
      "timestamp": "2025-06-30 14:31:02.356220",
      "response_time": 0.004694938659667969,
      "status_code": 0,
      "success": false,
      "error_message": "HTTPConnectionPool(host='localhost', port=80): Max retries exceeded with url: /api/ask (Caused by NewConnectionError('<urllib3.connection.HTTPConnection object at 0x104e9bce0>: Failed to establish a new connection: [Errno 61] Connection refused'))",
      "response_size": 0
    },
    {
      "timestamp": "2025-06-30 14:31:02.521943",
      "response_time": 0.00631403923034668,
      "status_code": 0,
      "success": false,
      "error_message": "HTTPConnectionPool(host='localhost', port=80): Max retries exceeded with url: /docs (Caused by NewConnectionError('<urllib3.connection.HTTPConnection object at 0x104f746b0>: Failed to establish a new connection: [Errno 61] Connection refused'))",
      "response_size": 0
    },
    {
      "timestamp": "2025-06-30 14:31:02.522344",
      "response_time": 0.0064220428466796875,
      "status_code": 0,
      "success": false,
      "error_message": "HTTPConnectionPool(host='localhost', port=80): Max retries exceeded with url: /health (Caused by NewConnectionError('<urllib3.connection.HTTPConnection object at 0x104f76030>: Failed to establish a new connection: [Errno 61] Connection refused'))",
      "response_size": 0
    },
    {
      "timestamp": "2025-06-30 14:31:02.525077",
      "response_time": 0.004589080810546875,
      "status_code": 0,
      "success": false,
      "error_message": "HTTPConnectionPool(host='localhost', port=80): Max retries exceeded with url: /api/ask (Caused by NewConnectionError('<urllib3.connection.HTTPConnection object at 0x104e9abe0>: Failed to establish a new connection: [Errno 61] Connection refused'))",
      "response_size": 0
    },
    {
      "timestamp": "2025-06-30 14:31:02.584393",
      "response_time": 0.003734588623046875,
      "status_code": 0,
      "success": false,
      "error_message": "HTTPConnectionPool(host='localhost', port=80): Max retries exceeded with url: /docs (Caused by NewConnectionError('<urllib3.connection.HTTPConnection object at 0x104e9b130>: Failed to establish a new connection: [Errno 61] Connection refused'))",
      "response_size": 0
    },
    {
      "timestamp": "2025-06-30 14:31:02.862638",
      "response_time": 0.003545999526977539,
      "status_code": 0,
      "success": false,
      "error_message": "HTTPConnectionPool(host='localhost', port=80): Max retries exceeded with url: /metrics (Caused by NewConnectionError('<urllib3.connection.HTTPConnection object at 0x104e99150>: Failed to establish a new connection: [Errno 61] Connection refused'))",
      "response_size": 0
    },
    {
      "timestamp": "2025-06-30 14:31:03.032421",
      "response_time": 0.00529789924621582,
      "status_code": 0,
      "success": false,
      "error_message": "HTTPConnectionPool(host='localhost', port=80): Max retries exceeded with url: /api/ask (Caused by NewConnectionError('<urllib3.connection.HTTPConnection object at 0x104e9b8a0>: Failed to establish a new connection: [Errno 61] Connection refused'))",
      "response_size": 0
    },
    {
      "timestamp": "2025-06-30 14:31:03.033474",
      "response_time": 0.0047969818115234375,
      "status_code": 0,
      "success": false,
      "error_message": "HTTPConnectionPool(host='localhost', port=80): Max retries exceeded with url: /api/ask (Caused by NewConnectionError('<urllib3.connection.HTTPConnection object at 0x104e9acf0>: Failed to establish a new connection: [Errno 61] Connection refused'))",
      "response_size": 0
    },
    {
      "timestamp": "2025-06-30 14:31:03.034326",
      "response_time": 0.004058122634887695,
      "status_code": 0,
      "success": false,
      "error_message": "HTTPConnectionPool(host='localhost', port=80): Max retries exceeded with url: /api/ask (Caused by NewConnectionError('<urllib3.connection.HTTPConnection object at 0x104e9bac0>: Failed to establish a new connection: [Errno 61] Connection refused'))",
      "response_size": 0
    },
    {
      "timestamp": "2025-06-30 14:31:03.088291",
      "response_time": 0.003281831741333008,
      "status_code": 0,
      "success": false,
      "error_message": "HTTPConnectionPool(host='localhost', port=80): Max retries exceeded with url: /api/ask (Caused by NewConnectionError('<urllib3.connection.HTTPConnection object at 0x104e9b240>: Failed to establish a new connection: [Errno 61] Connection refused'))",
      "response_size": 0
    },
    {
      "timestamp": "2025-06-30 14:31:03.367616",
      "response_time": 0.003939628601074219,
      "status_code": 0,
      "success": false,
      "error_message": "HTTPConnectionPool(host='localhost', port=80): Max retries exceeded with url: /api/ask (Caused by NewConnectionError('<urllib3.connection.HTTPConnection object at 0x104e9b350>: Failed to establish a new connection: [Errno 61] Connection refused'))",
      "response_size": 0
    },
    {
      "timestamp": "2025-06-30 14:31:03.538995",
      "response_time": 0.0037598609924316406,
      "status_code": 0,
      "success": false,
      "error_message": "HTTPConnectionPool(host='localhost', port=80): Max retries exceeded with url: /api/ask (Caused by NewConnectionError('<urllib3.connection.HTTPConnection object at 0x104e9b570>: Failed to establish a new connection: [Errno 61] Connection refused'))",
      "response_size": 0
    },
    {
      "timestamp": "2025-06-30 14:31:03.542781",
      "response_time": 0.0022230148315429688,
      "status_code": 0,
      "success": false,
      "error_message": "HTTPConnectionPool(host='localhost', port=80): Max retries exceeded with url: /api/ask (Caused by NewConnectionError('<urllib3.connection.HTTPConnection object at 0x104e9b9b0>: Failed to establish a new connection: [Errno 61] Connection refused'))",
      "response_size": 0
    },
    {
      "timestamp": "2025-06-30 14:31:03.593035",
      "response_time": 0.003439188003540039,
      "status_code": 0,
      "success": false,
      "error_message": "HTTPConnectionPool(host='localhost', port=80): Max retries exceeded with url: /api/ask (Caused by NewConnectionError('<urllib3.connection.HTTPConnection object at 0x104e99f20>: Failed to establish a new connection: [Errno 61] Connection refused'))",
      "response_size": 0
    },
    {
      "timestamp": "2025-06-30 14:31:03.876666",
      "response_time": 0.0037491321563720703,
      "status_code": 0,
      "success": false,
      "error_message": "HTTPConnectionPool(host='localhost', port=80): Max retries exceeded with url: /api/ask (Caused by NewConnectionError('<urllib3.connection.HTTPConnection object at 0x104e9b020>: Failed to establish a new connection: [Errno 61] Connection refused'))",
      "response_size": 0
    },
    {
      "timestamp": "2025-06-30 14:31:04.044024",
      "response_time": 0.004766941070556641,
      "status_code": 0,
      "success": false,
      "error_message": "HTTPConnectionPool(host='localhost', port=80): Max retries exceeded with url: /api/ask (Caused by NewConnectionError('<urllib3.connection.HTTPConnection object at 0x104e9bf00>: Failed to establish a new connection: [Errno 61] Connection refused'))",
      "response_size": 0
    },
    {
      "timestamp": "2025-06-30 14:31:04.047048",
      "response_time": 0.002580881118774414,
      "status_code": 0,
      "success": false,
      "error_message": "HTTPConnectionPool(host='localhost', port=80): Max retries exceeded with url: /api/ask (Caused by NewConnectionError('<urllib3.connection.HTTPConnection object at 0x104e9a140>: Failed to establish a new connection: [Errno 61] Connection refused'))",
      "response_size": 0
    },
    {
      "timestamp": "2025-06-30 14:31:04.101599",
      "response_time": 0.004349946975708008,
      "status_code": 0,
      "success": false,
      "error_message": "HTTPConnectionPool(host='localhost', port=80): Max retries exceeded with url: /api/ask (Caused by NewConnectionError('<urllib3.connection.HTTPConnection object at 0x104f77460>: Failed to establish a new connection: [Errno 61] Connection refused'))",
      "response_size": 0
    },
    {
      "timestamp": "2025-06-30 14:31:04.384358",
      "response_time": 0.004626035690307617,
      "status_code": 0,
      "success": false,
      "error_message": "HTTPConnectionPool(host='localhost', port=80): Max retries exceeded with url: /api/ask (Caused by NewConnectionError('<urllib3.connection.HTTPConnection object at 0x104f768b0>: Failed to establish a new connection: [Errno 61] Connection refused'))",
      "response_size": 0
    },
    {
      "timestamp": "2025-06-30 14:31:04.550363",
      "response_time": 0.0067291259765625,
      "status_code": 0,
      "success": false,
      "error_message": "HTTPConnectionPool(host='localhost', port=80): Max retries exceeded with url: /api/ask (Caused by NewConnectionError('<urllib3.connection.HTTPConnection object at 0x104e9a140>: Failed to establish a new connection: [Errno 61] Connection refused'))",
      "response_size": 0
    },
    {
      "timestamp": "2025-06-30 14:31:04.550747",
      "response_time": 0.006727933883666992,
      "status_code": 0,
      "success": false,
      "error_message": "HTTPConnectionPool(host='localhost', port=80): Max retries exceeded with url: /api/ask (Caused by NewConnectionError('<urllib3.connection.HTTPConnection object at 0x104e9bbd0>: Failed to establish a new connection: [Errno 61] Connection refused'))",
      "response_size": 0
    },
    {
      "timestamp": "2025-06-30 14:31:04.890178",
      "response_time": 0.0012941360473632812,
      "status_code": 0,
      "success": false,
      "error_message": "HTTPConnectionPool(host='localhost', port=80): Max retries exceeded with url: /health (Caused by NewConnectionError('<urllib3.connection.HTTPConnection object at 0x104e9b020>: Failed to establish a new connection: [Errno 61] Connection refused'))",
      "response_size": 0
    },
    {
      "timestamp": "2025-06-30 14:31:05.062560",
      "response_time": 0.0034470558166503906,
      "status_code": 0,
      "success": false,
      "error_message": "HTTPConnectionPool(host='localhost', port=80): Max retries exceeded with url: /health (Caused by NewConnectionError('<urllib3.connection.HTTPConnection object at 0x104e99f20>: Failed to establish a new connection: [Errno 61] Connection refused'))",
      "response_size": 0
    },
    {
      "timestamp": "2025-06-30 14:31:05.062197",
      "response_time": 0.004149198532104492,
      "status_code": 0,
      "success": false,
      "error_message": "HTTPConnectionPool(host='localhost', port=80): Max retries exceeded with url: /api/ask (Caused by NewConnectionError('<urllib3.connection.HTTPConnection object at 0x104e9b680>: Failed to establish a new connection: [Errno 61] Connection refused'))",
      "response_size": 0
    },
    {
      "timestamp": "2025-06-30 14:31:05.396567",
      "response_time": 0.0046770572662353516,
      "status_code": 0,
      "success": false,
      "error_message": "HTTPConnectionPool(host='localhost', port=80): Max retries exceeded with url: /api/ask (Caused by NewConnectionError('<urllib3.connection.HTTPConnection object at 0x104e9b570>: Failed to establish a new connection: [Errno 61] Connection refused'))",
      "response_size": 0
    },
    {
      "timestamp": "2025-06-30 14:31:05.567647",
      "response_time": 0.0041615962982177734,
      "status_code": 0,
      "success": false,
      "error_message": "HTTPConnectionPool(host='localhost', port=80): Max retries exceeded with url: /api/ask (Caused by NewConnectionError('<urllib3.connection.HTTPConnection object at 0x104e9b350>: Failed to establish a new connection: [Errno 61] Connection refused'))",
      "response_size": 0
    },
    {
      "timestamp": "2025-06-30 14:31:05.570795",
      "response_time": 0.002463102340698242,
      "status_code": 0,
      "success": false,
      "error_message": "HTTPConnectionPool(host='localhost', port=80): Max retries exceeded with url: /metrics (Caused by NewConnectionError('<urllib3.connection.HTTPConnection object at 0x104e9b240>: Failed to establish a new connection: [Errno 61] Connection refused'))",
      "response_size": 0
    },
    {
      "timestamp": "2025-06-30 14:31:05.903207",
      "response_time": 0.0033369064331054688,
      "status_code": 0,
      "success": false,
      "error_message": "HTTPConnectionPool(host='localhost', port=80): Max retries exceeded with url: /metrics (Caused by NewConnectionError('<urllib3.connection.HTTPConnection object at 0x104e9bac0>: Failed to establish a new connection: [Errno 61] Connection refused'))",
      "response_size": 0
    },
    {
      "timestamp": "2025-06-30 14:31:06.076905",
      "response_time": 0.003454923629760742,
      "status_code": 0,
      "success": false,
      "error_message": "HTTPConnectionPool(host='localhost', port=80): Max retries exceeded with url: /health (Caused by NewConnectionError('<urllib3.connection.HTTPConnection object at 0x104e9acf0>: Failed to establish a new connection: [Errno 61] Connection refused'))",
      "response_size": 0
    },
    {
      "timestamp": "2025-06-30 14:31:06.410453",
      "response_time": 0.004057884216308594,
      "status_code": 0,
      "success": false,
      "error_message": "HTTPConnectionPool(host='localhost', port=80): Max retries exceeded with url: /docs (Caused by NewConnectionError('<urllib3.connection.HTTPConnection object at 0x104e9b8a0>: Failed to establish a new connection: [Errno 61] Connection refused'))",
      "response_size": 0
    },
    {
      "timestamp": "2025-06-30 14:31:06.583879",
      "response_time": 0.003972053527832031,
      "status_code": 0,
      "success": false,
      "error_message": "HTTPConnectionPool(host='localhost', port=80): Max retries exceeded with url: /api/ask (Caused by NewConnectionError('<urllib3.connection.HTTPConnection object at 0x104e99150>: Failed to establish a new connection: [Errno 61] Connection refused'))",
      "response_size": 0
    },
    {
      "timestamp": "2025-06-30 14:31:06.919070",
      "response_time": 0.003532886505126953,
      "status_code": 0,
      "success": false,
      "error_message": "HTTPConnectionPool(host='localhost', port=80): Max retries exceeded with url: /api/ask (Caused by NewConnectionError('<urllib3.connection.HTTPConnection object at 0x104e9b130>: Failed to establish a new connection: [Errno 61] Connection refused'))",
      "response_size": 0
    },
    {
      "timestamp": "2025-06-30 14:31:07.427546",
      "response_time": 0.004106998443603516,
      "status_code": 0,
      "success": false,
      "error_message": "HTTPConnectionPool(host='localhost', port=80): Max retries exceeded with url: /api/ask (Caused by NewConnectionError('<urllib3.connection.HTTPConnection object at 0x104e9abe0>: Failed to establish a new connection: [Errno 61] Connection refused'))",
      "response_size": 0
    },
    {
      "timestamp": "2025-06-30 14:31:07.936774",
      "response_time": 0.003648042678833008,
      "status_code": 0,
      "success": false,
      "error_message": "HTTPConnectionPool(host='localhost', port=80): Max retries exceeded with url: /docs (Caused by NewConnectionError('<urllib3.connection.HTTPConnection object at 0x104e9ae00>: Failed to establish a new connection: [Errno 61] Connection refused'))",
      "response_size": 0
    }
  ]
}