{
  "test_timestamp": "20250630_142820",
  "test_config": {
    "base_url": "http://localhost",
    "port": 80,
    "num_concurrent_users": 5,
    "num_requests_per_user": 20,
    "ramp_up_time": 10,
    "test_duration": 300,
    "request_timeout": 30,
    "think_time": 0.5
  },
  "results": {
    "total_requests": 100,
    "successful_requests": 0,
    "failed_requests": 100,
    "average_response_time": 0.0037607765197753907,
    "median_response_time": 0.0037709474563598633,
    "p95_response_time": 0.005174505710601807,
    "p99_response_time": 0.010557982921600342,
    "min_response_time": 0.0015530586242675781,
    "max_response_time": 0.010601043701171875,
    "requests_per_second": 5.663623469625223,
    "error_rate": 100.0,
    "test_duration": 17.656541,
    "concurrent_users": 5
  },
  "detailed_results": [
    {
      "timestamp": "2025-06-30 14:28:02.507008",
      "response_time": 0.003280162811279297,
      "status_code": 0,
      "success": false,
      "error_message": "HTTPConnectionPool(host='localhost', port=80): Max retries exceeded with url: /api/ask (Caused by NewConnectionError('<urllib3.connection.HTTPConnection object at 0x104e83d10>: Failed to establish a new connection: [Errno 61] Connection refused'))",
      "response_size": 0
    },
    {
      "timestamp": "2025-06-30 14:28:03.015462",
      "response_time": 0.003774881362915039,
      "status_code": 0,
      "success": false,
      "error_message": "HTTPConnectionPool(host='localhost', port=80): Max retries exceeded with url: /metrics (Caused by NewConnectionError('<urllib3.connection.HTTPConnection object at 0x104e9b680>: Failed to establish a new connection: [Errno 61] Connection refused'))",
      "response_size": 0
    },
    {
      "timestamp": "2025-06-30 14:28:03.521537",
      "response_time": 0.0023279190063476562,
      "status_code": 0,
      "success": false,
      "error_message": "HTTPConnectionPool(host='localhost', port=80): Max retries exceeded with url: /docs (Caused by NewConnectionError('<urllib3.connection.HTTPConnection object at 0x104e9bdf0>: Failed to establish a new connection: [Errno 61] Connection refused'))",
      "response_size": 0
    },
    {
      "timestamp": "2025-06-30 14:28:04.028970",
      "response_time": 0.004308938980102539,
      "status_code": 0,
      "success": false,
      "error_message": "HTTPConnectionPool(host='localhost', port=80): Max retries exceeded with url: /health (Caused by NewConnectionError('<urllib3.connection.HTTPConnection object at 0x104f24050>: Failed to establish a new connection: [Errno 61] Connection refused'))",
      "response_size": 0
    },
    {
      "timestamp": "2025-06-30 14:28:04.512625",
      "response_time": 0.004816770553588867,
      "status_code": 0,
      "success": false,
      "error_message": "HTTPConnectionPool(host='localhost', port=80): Max retries exceeded with url: /metrics (Caused by NewConnectionError('<urllib3.connection.HTTPConnection object at 0x104f24270>: Failed to establish a new connection: [Errno 61] Connection refused'))",
      "response_size": 0
    },
    {
      "timestamp": "2025-06-30 14:28:04.538203",
      "response_time": 0.004525184631347656,
      "status_code": 0,
      "success": false,
      "error_message": "HTTPConnectionPool(host='localhost', port=80): Max retries exceeded with url: /api/ask (Caused by NewConnectionError('<urllib3.connection.HTTPConnection object at 0x104f245a0>: Failed to establish a new connection: [Errno 61] Connection refused'))",
      "response_size": 0
    },
    {
      "timestamp": "2025-06-30 14:28:05.019272",
      "response_time": 0.0032448768615722656,
      "status_code": 0,
      "success": false,
      "error_message": "HTTPConnectionPool(host='localhost', port=80): Max retries exceeded with url: /api/ask (Caused by NewConnectionError('<urllib3.connection.HTTPConnection object at 0x104f247c0>: Failed to establish a new connection: [Errno 61] Connection refused'))",
      "response_size": 0
    },
    {
      "timestamp": "2025-06-30 14:28:05.042950",
      "response_time": 0.003025054931640625,
      "status_code": 0,
      "success": false,
      "error_message": "HTTPConnectionPool(host='localhost', port=80): Max retries exceeded with url: /api/ask (Caused by NewConnectionError('<urllib3.connection.HTTPConnection object at 0x104f24af0>: Failed to establish a new connection: [Errno 61] Connection refused'))",
      "response_size": 0
    },
    {
      "timestamp": "2025-06-30 14:28:05.527634",
      "response_time": 0.003801107406616211,
      "status_code": 0,
      "success": false,
      "error_message": "HTTPConnectionPool(host='localhost', port=80): Max retries exceeded with url: /api/ask (Caused by NewConnectionError('<urllib3.connection.HTTPConnection object at 0x104f24e20>: Failed to establish a new connection: [Errno 61] Connection refused'))",
      "response_size": 0
    },
    {
      "timestamp": "2025-06-30 14:28:05.551114",
      "response_time": 0.003832101821899414,
      "status_code": 0,
      "success": false,
      "error_message": "HTTPConnectionPool(host='localhost', port=80): Max retries exceeded with url: /api/ask (Caused by NewConnectionError('<urllib3.connection.HTTPConnection object at 0x104e9b8a0>: Failed to establish a new connection: [Errno 61] Connection refused'))",
      "response_size": 0
    },
    {
      "timestamp": "2025-06-30 14:28:06.036545",
      "response_time": 0.0048792362213134766,
      "status_code": 0,
      "success": false,
      "error_message": "HTTPConnectionPool(host='localhost', port=80): Max retries exceeded with url: /metrics (Caused by NewConnectionError('<urllib3.connection.HTTPConnection object at 0x104e9b9b0>: Failed to establish a new connection: [Errno 61] Connection refused'))",
      "response_size": 0
    },
    {
      "timestamp": "2025-06-30 14:28:06.058301",
      "response_time": 0.0031900405883789062,
      "status_code": 0,
      "success": false,
      "error_message": "HTTPConnectionPool(host='localhost', port=80): Max retries exceeded with url: /api/ask (Caused by NewConnectionError('<urllib3.connection.HTTPConnection object at 0x104e9bdf0>: Failed to establish a new connection: [Errno 61] Connection refused'))",
      "response_size": 0
    },
    {
      "timestamp": "2025-06-30 14:28:06.508536",
      "response_time": 0.0032160282135009766,
      "status_code": 0,
      "success": false,
      "error_message": "HTTPConnectionPool(host='localhost', port=80): Max retries exceeded with url: /health (Caused by NewConnectionError('<urllib3.connection.HTTPConnection object at 0x104e9bce0>: Failed to establish a new connection: [Errno 61] Connection refused'))",
      "response_size": 0
    },
    {
      "timestamp": "2025-06-30 14:28:06.546543",
      "response_time": 0.0042459964752197266,
      "status_code": 0,
      "success": false,
      "error_message": "HTTPConnectionPool(host='localhost', port=80): Max retries exceeded with url: /api/ask (Caused by NewConnectionError('<urllib3.connection.HTTPConnection object at 0x104e9b240>: Failed to establish a new connection: [Errno 61] Connection refused'))",
      "response_size": 0
    },
    {
      "timestamp": "2025-06-30 14:28:06.562138",
      "response_time": 0.003471851348876953,
      "status_code": 0,
      "success": false,
      "error_message": "HTTPConnectionPool(host='localhost', port=80): Max retries exceeded with url: /api/ask (Caused by NewConnectionError('<urllib3.connection.HTTPConnection object at 0x104e9b680>: Failed to establish a new connection: [Errno 61] Connection refused'))",
      "response_size": 0
    },
    {
      "timestamp": "2025-06-30 14:28:07.016821",
      "response_time": 0.0018723011016845703,
      "status_code": 0,
      "success": false,
      "error_message": "HTTPConnectionPool(host='localhost', port=80): Max retries exceeded with url: /api/ask (Caused by NewConnectionError('<urllib3.connection.HTTPConnection object at 0x104e9b570>: Failed to establish a new connection: [Errno 61] Connection refused'))",
      "response_size": 0
    },
    {
      "timestamp": "2025-06-30 14:28:07.055875",
      "response_time": 0.004339933395385742,
      "status_code": 0,
      "success": false,
      "error_message": "HTTPConnectionPool(host='localhost', port=80): Max retries exceeded with url: /api/ask (Caused by NewConnectionError('<urllib3.connection.HTTPConnection object at 0x104e9acf0>: Failed to establish a new connection: [Errno 61] Connection refused'))",
      "response_size": 0
    },
    {
      "timestamp": "2025-06-30 14:28:07.070679",
      "response_time": 0.003815889358520508,
      "status_code": 0,
      "success": false,
      "error_message": "HTTPConnectionPool(host='localhost', port=80): Max retries exceeded with url: /api/ask (Caused by NewConnectionError('<urllib3.connection.HTTPConnection object at 0x104e9abe0>: Failed to establish a new connection: [Errno 61] Connection refused'))",
      "response_size": 0
    },
    {
      "timestamp": "2025-06-30 14:28:07.522498",
      "response_time": 0.004761934280395508,
      "status_code": 0,
      "success": false,
      "error_message": "HTTPConnectionPool(host='localhost', port=80): Max retries exceeded with url: /api/ask (Caused by NewConnectionError('<urllib3.connection.HTTPConnection object at 0x104e9a8b0>: Failed to establish a new connection: [Errno 61] Connection refused'))",
      "response_size": 0
    },
    {
      "timestamp": "2025-06-30 14:28:07.561408",
      "response_time": 0.0034601688385009766,
      "status_code": 0,
      "success": false,
      "error_message": "HTTPConnectionPool(host='localhost', port=80): Max retries exceeded with url: /api/ask (Caused by NewConnectionError('<urllib3.connection.HTTPConnection object at 0x104e9a690>: Failed to establish a new connection: [Errno 61] Connection refused'))",
      "response_size": 0
    },
    {
      "timestamp": "2025-06-30 14:28:07.575499",
      "response_time": 0.002880096435546875,
      "status_code": 0,
      "success": false,
      "error_message": "HTTPConnectionPool(host='localhost', port=80): Max retries exceeded with url: /docs (Caused by NewConnectionError('<urllib3.connection.HTTPConnection object at 0x104e9a360>: Failed to establish a new connection: [Errno 61] Connection refused'))",
      "response_size": 0
    },
    {
      "timestamp": "2025-06-30 14:28:08.029007",
      "response_time": 0.004644155502319336,
      "status_code": 0,
      "success": false,
      "error_message": "HTTPConnectionPool(host='localhost', port=80): Max retries exceeded with url: /docs (Caused by NewConnectionError('<urllib3.connection.HTTPConnection object at 0x104e9a250>: Failed to establish a new connection: [Errno 61] Connection refused'))",
      "response_size": 0
    },
    {
      "timestamp": "2025-06-30 14:28:08.069969",
      "response_time": 0.0022339820861816406,
      "status_code": 0,
      "success": false,
      "error_message": "HTTPConnectionPool(host='localhost', port=80): Max retries exceeded with url: /api/ask (Caused by NewConnectionError('<urllib3.connection.HTTPConnection object at 0x104e9a140>: Failed to establish a new connection: [Errno 61] Connection refused'))",
      "response_size": 0
    },
    {
      "timestamp": "2025-06-30 14:28:08.081731",
      "response_time": 0.0015530586242675781,
      "status_code": 0,
      "success": false,
      "error_message": "HTTPConnectionPool(host='localhost', port=80): Max retries exceeded with url: /api/ask (Caused by NewConnectionError('<urllib3.connection.HTTPConnection object at 0x104e98e20>: Failed to establish a new connection: [Errno 61] Connection refused'))",
      "response_size": 0
    },
    {
      "timestamp": "2025-06-30 14:28:08.513492",
      "response_time": 0.004630088806152344,
      "status_code": 0,
      "success": false,
      "error_message": "HTTPConnectionPool(host='localhost', port=80): Max retries exceeded with url: /api/ask (Caused by NewConnectionError('<urllib3.connection.HTTPConnection object at 0x104e99260>: Failed to establish a new connection: [Errno 61] Connection refused'))",
      "response_size": 0
    },
    {
      "timestamp": "2025-06-30 14:28:08.538214",
      "response_time": 0.003905057907104492,
      "status_code": 0,
      "success": false,
      "error_message": "HTTPConnectionPool(host='localhost', port=80): Max retries exceeded with url: /docs (Caused by NewConnectionError('<urllib3.connection.HTTPConnection object at 0x104e9a140>: Failed to establish a new connection: [Errno 61] Connection refused'))",
      "response_size": 0
    },
    {
      "timestamp": "2025-06-30 14:28:08.577280",
      "response_time": 0.004170894622802734,
      "status_code": 0,
      "success": false,
      "error_message": "HTTPConnectionPool(host='localhost', port=80): Max retries exceeded with url: /docs (Caused by NewConnectionError('<urllib3.connection.HTTPConnection object at 0x104e9a250>: Failed to establish a new connection: [Errno 61] Connection refused'))",
      "response_size": 0
    },
    {
      "timestamp": "2025-06-30 14:28:08.588337",
      "response_time": 0.0042340755462646484,
      "status_code": 0,
      "success": false,
      "error_message": "HTTPConnectionPool(host='localhost', port=80): Max retries exceeded with url: /metrics (Caused by NewConnectionError('<urllib3.connection.HTTPConnection object at 0x104e9a360>: Failed to establish a new connection: [Errno 61] Connection refused'))",
      "response_size": 0
    },
    {
      "timestamp": "2025-06-30 14:28:09.022486",
      "response_time": 0.005186796188354492,
      "status_code": 0,
      "success": false,
      "error_message": "HTTPConnectionPool(host='localhost', port=80): Max retries exceeded with url: /api/ask (Caused by NewConnectionError('<urllib3.connection.HTTPConnection object at 0x104e9a690>: Failed to establish a new connection: [Errno 61] Connection refused'))",
      "response_size": 0
    },
    {
      "timestamp": "2025-06-30 14:28:09.047219",
      "response_time": 0.002628803253173828,
      "status_code": 0,
      "success": false,
      "error_message": "HTTPConnectionPool(host='localhost', port=80): Max retries exceeded with url: /api/ask (Caused by NewConnectionError('<urllib3.connection.HTTPConnection object at 0x104e9a8b0>: Failed to establish a new connection: [Errno 61] Connection refused'))",
      "response_size": 0
    },
    {
      "timestamp": "2025-06-30 14:28:09.086578",
      "response_time": 0.003103017807006836,
      "status_code": 0,
      "success": false,
      "error_message": "HTTPConnectionPool(host='localhost', port=80): Max retries exceeded with url: /api/ask (Caused by NewConnectionError('<urllib3.connection.HTTPConnection object at 0x104e9abe0>: Failed to establish a new connection: [Errno 61] Connection refused'))",
      "response_size": 0
    },
    {
      "timestamp": "2025-06-30 14:28:09.097629",
      "response_time": 0.0017609596252441406,
      "status_code": 0,
      "success": false,
      "error_message": "HTTPConnectionPool(host='localhost', port=80): Max retries exceeded with url: /api/ask (Caused by NewConnectionError('<urllib3.connection.HTTPConnection object at 0x104e9acf0>: Failed to establish a new connection: [Errno 61] Connection refused'))",
      "response_size": 0
    },
    {
      "timestamp": "2025-06-30 14:28:09.530310",
      "response_time": 0.004698038101196289,
      "status_code": 0,
      "success": false,
      "error_message": "HTTPConnectionPool(host='localhost', port=80): Max retries exceeded with url: /api/ask (Caused by NewConnectionError('<urllib3.connection.HTTPConnection object at 0x104e9b570>: Failed to establish a new connection: [Errno 61] Connection refused'))",
      "response_size": 0
    },
    {
      "timestamp": "2025-06-30 14:28:09.554936",
      "response_time": 0.0035440921783447266,
      "status_code": 0,
      "success": false,
      "error_message": "HTTPConnectionPool(host='localhost', port=80): Max retries exceeded with url: /api/ask (Caused by NewConnectionError('<urllib3.connection.HTTPConnection object at 0x104e9b680>: Failed to establish a new connection: [Errno 61] Connection refused'))",
      "response_size": 0
    },
    {
      "timestamp": "2025-06-30 14:28:09.589997",
      "response_time": 0.00273895263671875,
      "status_code": 0,
      "success": false,
      "error_message": "HTTPConnectionPool(host='localhost', port=80): Max retries exceeded with url: /api/ask (Caused by NewConnectionError('<urllib3.connection.HTTPConnection object at 0x104e9b240>: Failed to establish a new connection: [Errno 61] Connection refused'))",
      "response_size": 0
    },
    {
      "timestamp": "2025-06-30 14:28:09.599624",
      "response_time": 0.0023763179779052734,
      "status_code": 0,
      "success": false,
      "error_message": "HTTPConnectionPool(host='localhost', port=80): Max retries exceeded with url: /api/ask (Caused by NewConnectionError('<urllib3.connection.HTTPConnection object at 0x104e9bce0>: Failed to establish a new connection: [Errno 61] Connection refused'))",
      "response_size": 0
    },
    {
      "timestamp": "2025-06-30 14:28:10.039214",
      "response_time": 0.0039708614349365234,
      "status_code": 0,
      "success": false,
      "error_message": "HTTPConnectionPool(host='localhost', port=80): Max retries exceeded with url: /metrics (Caused by NewConnectionError('<urllib3.connection.HTTPConnection object at 0x104e9bdf0>: Failed to establish a new connection: [Errno 61] Connection refused'))",
      "response_size": 0
    },
    {
      "timestamp": "2025-06-30 14:28:10.061922",
      "response_time": 0.0040361881256103516,
      "status_code": 0,
      "success": false,
      "error_message": "HTTPConnectionPool(host='localhost', port=80): Max retries exceeded with url: /api/ask (Caused by NewConnectionError('<urllib3.connection.HTTPConnection object at 0x104e9b9b0>: Failed to establish a new connection: [Errno 61] Connection refused'))",
      "response_size": 0
    },
    {
      "timestamp": "2025-06-30 14:28:10.097840",
      "response_time": 0.0030961036682128906,
      "status_code": 0,
      "success": false,
      "error_message": "HTTPConnectionPool(host='localhost', port=80): Max retries exceeded with url: /api/ask (Caused by NewConnectionError('<urllib3.connection.HTTPConnection object at 0x104e9b8a0>: Failed to establish a new connection: [Errno 61] Connection refused'))",
      "response_size": 0
    },
    {
      "timestamp": "2025-06-30 14:28:10.102620",
      "response_time": 0.0021369457244873047,
      "status_code": 0,
      "success": false,
      "error_message": "HTTPConnectionPool(host='localhost', port=80): Max retries exceeded with url: /api/ask (Caused by NewConnectionError('<urllib3.connection.HTTPConnection object at 0x104e999d0>: Failed to establish a new connection: [Errno 61] Connection refused'))",
      "response_size": 0
    },
    {
      "timestamp": "2025-06-30 14:28:10.513584",
      "response_time": 0.003004789352416992,
      "status_code": 0,
      "success": false,
      "error_message": "HTTPConnectionPool(host='localhost', port=80): Max retries exceeded with url: /docs (Caused by NewConnectionError('<urllib3.connection.HTTPConnection object at 0x104f24e20>: Failed to establish a new connection: [Errno 61] Connection refused'))",
      "response_size": 0
    },
    {
      "timestamp": "2025-06-30 14:28:10.546963",
      "response_time": 0.002312898635864258,
      "status_code": 0,
      "success": false,
      "error_message": "HTTPConnectionPool(host='localhost', port=80): Max retries exceeded with url: /api/ask (Caused by NewConnectionError('<urllib3.connection.HTTPConnection object at 0x104e99f20>: Failed to establish a new connection: [Errno 61] Connection refused'))",
      "response_size": 0
    },
    {
      "timestamp": "2025-06-30 14:28:10.566924",
      "response_time": 0.0021898746490478516,
      "status_code": 0,
      "success": false,
      "error_message": "HTTPConnectionPool(host='localhost', port=80): Max retries exceeded with url: /api/ask (Caused by NewConnectionError('<urllib3.connection.HTTPConnection object at 0x104e9bac0>: Failed to establish a new connection: [Errno 61] Connection refused'))",
      "response_size": 0
    },
    {
      "timestamp": "2025-06-30 14:28:10.606166",
      "response_time": 0.003075122833251953,
      "status_code": 0,
      "success": false,
      "error_message": "HTTPConnectionPool(host='localhost', port=80): Max retries exceeded with url: /api/ask (Caused by NewConnectionError('<urllib3.connection.HTTPConnection object at 0x104e9bbd0>: Failed to establish a new connection: [Errno 61] Connection refused'))",
      "response_size": 0
    },
    {
      "timestamp": "2025-06-30 14:28:10.605810",
      "response_time": 0.0036890506744384766,
      "status_code": 0,
      "success": false,
      "error_message": "HTTPConnectionPool(host='localhost', port=80): Max retries exceeded with url: /api/ask (Caused by NewConnectionError('<urllib3.connection.HTTPConnection object at 0x104e9bdf0>: Failed to establish a new connection: [Errno 61] Connection refused'))",
      "response_size": 0
    },
    {
      "timestamp": "2025-06-30 14:28:11.021592",
      "response_time": 0.004940986633300781,
      "status_code": 0,
      "success": false,
      "error_message": "HTTPConnectionPool(host='localhost', port=80): Max retries exceeded with url: /api/ask (Caused by NewConnectionError('<urllib3.connection.HTTPConnection object at 0x104e9b130>: Failed to establish a new connection: [Errno 61] Connection refused'))",
      "response_size": 0
    },
    {
      "timestamp": "2025-06-30 14:28:11.050414",
      "response_time": 0.003509998321533203,
      "status_code": 0,
      "success": false,
      "error_message": "HTTPConnectionPool(host='localhost', port=80): Max retries exceeded with url: /api/ask (Caused by NewConnectionError('<urllib3.connection.HTTPConnection object at 0x104e9b460>: Failed to establish a new connection: [Errno 61] Connection refused'))",
      "response_size": 0
    },
    {
      "timestamp": "2025-06-30 14:28:11.072632",
      "response_time": 0.005753040313720703,
      "status_code": 0,
      "success": false,
      "error_message": "HTTPConnectionPool(host='localhost', port=80): Max retries exceeded with url: /api/ask (Caused by NewConnectionError('<urllib3.connection.HTTPConnection object at 0x104e9b790>: Failed to establish a new connection: [Errno 61] Connection refused'))",
      "response_size": 0
    },
    {
      "timestamp": "2025-06-30 14:28:11.111743",
      "response_time": 0.00456690788269043,
      "status_code": 0,
      "success": false,
      "error_message": "HTTPConnectionPool(host='localhost', port=80): Max retries exceeded with url: /api/ask (Caused by NewConnectionError('<urllib3.connection.HTTPConnection object at 0x104e9af10>: Failed to establish a new connection: [Errno 61] Connection refused'))",
      "response_size": 0
    },
    {
      "timestamp": "2025-06-30 14:28:11.114045",
      "response_time": 0.0030281543731689453,
      "status_code": 0,
      "success": false,
      "error_message": "HTTPConnectionPool(host='localhost', port=80): Max retries exceeded with url: /api/ask (Caused by NewConnectionError('<urllib3.connection.HTTPConnection object at 0x104e9acf0>: Failed to establish a new connection: [Errno 61] Connection refused'))",
      "response_size": 0
    },
    {
      "timestamp": "2025-06-30 14:28:11.531647",
      "response_time": 0.004209995269775391,
      "status_code": 0,
      "success": false,
      "error_message": "HTTPConnectionPool(host='localhost', port=80): Max retries exceeded with url: /api/ask (Caused by NewConnectionError('<urllib3.connection.HTTPConnection object at 0x104e9a7a0>: Failed to establish a new connection: [Errno 61] Connection refused'))",
      "response_size": 0
    },
    {
      "timestamp": "2025-06-30 14:28:11.557258",
      "response_time": 0.003695249557495117,
      "status_code": 0,
      "success": false,
      "error_message": "HTTPConnectionPool(host='localhost', port=80): Max retries exceeded with url: /api/ask (Caused by NewConnectionError('<urllib3.connection.HTTPConnection object at 0x104e9a9c0>: Failed to establish a new connection: [Errno 61] Connection refused'))",
      "response_size": 0
    },
    {
      "timestamp": "2025-06-30 14:28:11.583467",
      "response_time": 0.0022280216217041016,
      "status_code": 0,
      "success": false,
      "error_message": "HTTPConnectionPool(host='localhost', port=80): Max retries exceeded with url: /health (Caused by NewConnectionError('<urllib3.connection.HTTPConnection object at 0x104e9a580>: Failed to establish a new connection: [Errno 61] Connection refused'))",
      "response_size": 0
    },
    {
      "timestamp": "2025-06-30 14:28:11.617201",
      "response_time": 0.003650188446044922,
      "status_code": 0,
      "success": false,
      "error_message": "HTTPConnectionPool(host='localhost', port=80): Max retries exceeded with url: /api/ask (Caused by NewConnectionError('<urllib3.connection.HTTPConnection object at 0x104e9a470>: Failed to establish a new connection: [Errno 61] Connection refused'))",
      "response_size": 0
    },
    {
      "timestamp": "2025-06-30 14:28:11.622121",
      "response_time": 0.002887248992919922,
      "status_code": 0,
      "success": false,
      "error_message": "HTTPConnectionPool(host='localhost', port=80): Max retries exceeded with url: /metrics (Caused by NewConnectionError('<urllib3.connection.HTTPConnection object at 0x104e9a030>: Failed to establish a new connection: [Errno 61] Connection refused'))",
      "response_size": 0
    },
    {
      "timestamp": "2025-06-30 14:28:12.039175",
      "response_time": 0.0046329498291015625,
      "status_code": 0,
      "success": false,
      "error_message": "HTTPConnectionPool(host='localhost', port=80): Max retries exceeded with url: /api/ask (Caused by NewConnectionError('<urllib3.connection.HTTPConnection object at 0x104e99150>: Failed to establish a new connection: [Errno 61] Connection refused'))",
      "response_size": 0
    },
    {
      "timestamp": "2025-06-30 14:28:12.061721",
      "response_time": 0.003604888916015625,
      "status_code": 0,
      "success": false,
      "error_message": "HTTPConnectionPool(host='localhost', port=80): Max retries exceeded with url: /api/ask (Caused by NewConnectionError('<urllib3.connection.HTTPConnection object at 0x104e98e20>: Failed to establish a new connection: [Errno 61] Connection refused'))",
      "response_size": 0
    },
    {
      "timestamp": "2025-06-30 14:28:12.089153",
      "response_time": 0.006294965744018555,
      "status_code": 0,
      "success": false,
      "error_message": "HTTPConnectionPool(host='localhost', port=80): Max retries exceeded with url: /api/ask (Caused by NewConnectionError('<urllib3.connection.HTTPConnection object at 0x104e98e20>: Failed to establish a new connection: [Errno 61] Connection refused'))",
      "response_size": 0
    },
    {
      "timestamp": "2025-06-30 14:28:12.121570",
      "response_time": 0.004166126251220703,
      "status_code": 0,
      "success": false,
      "error_message": "HTTPConnectionPool(host='localhost', port=80): Max retries exceeded with url: /api/ask (Caused by NewConnectionError('<urllib3.connection.HTTPConnection object at 0x104e99260>: Failed to establish a new connection: [Errno 61] Connection refused'))",
      "response_size": 0
    },
    {
      "timestamp": "2025-06-30 14:28:12.126714",
      "response_time": 0.002485036849975586,
      "status_code": 0,
      "success": false,
      "error_message": "HTTPConnectionPool(host='localhost', port=80): Max retries exceeded with url: /api/ask (Caused by NewConnectionError('<urllib3.connection.HTTPConnection object at 0x104e9a140>: Failed to establish a new connection: [Errno 61] Connection refused'))",
      "response_size": 0
    },
    {
      "timestamp": "2025-06-30 14:28:12.548798",
      "response_time": 0.0038678646087646484,
      "status_code": 0,
      "success": false,
      "error_message": "HTTPConnectionPool(host='localhost', port=80): Max retries exceeded with url: /api/ask (Caused by NewConnectionError('<urllib3.connection.HTTPConnection object at 0x104e9a250>: Failed to establish a new connection: [Errno 61] Connection refused'))",
      "response_size": 0
    },
    {
      "timestamp": "2025-06-30 14:28:12.570392",
      "response_time": 0.0046231746673583984,
      "status_code": 0,
      "success": false,
      "error_message": "HTTPConnectionPool(host='localhost', port=80): Max retries exceeded with url: /api/ask (Caused by NewConnectionError('<urllib3.connection.HTTPConnection object at 0x104e9a360>: Failed to establish a new connection: [Errno 61] Connection refused'))",
      "response_size": 0
    },
    {
      "timestamp": "2025-06-30 14:28:12.600537",
      "response_time": 0.003676891326904297,
      "status_code": 0,
      "success": false,
      "error_message": "HTTPConnectionPool(host='localhost', port=80): Max retries exceeded with url: /api/ask (Caused by NewConnectionError('<urllib3.connection.HTTPConnection object at 0x104e9a690>: Failed to establish a new connection: [Errno 61] Connection refused'))",
      "response_size": 0
    },
    {
      "timestamp": "2025-06-30 14:28:12.634361",
      "response_time": 0.0034210681915283203,
      "status_code": 0,
      "success": false,
      "error_message": "HTTPConnectionPool(host='localhost', port=80): Max retries exceeded with url: /api/ask (Caused by NewConnectionError('<urllib3.connection.HTTPConnection object at 0x104e9a8b0>: Failed to establish a new connection: [Errno 61] Connection refused'))",
      "response_size": 0
    },
    {
      "timestamp": "2025-06-30 14:28:13.054947",
      "response_time": 0.003757953643798828,
      "status_code": 0,
      "success": false,
      "error_message": "HTTPConnectionPool(host='localhost', port=80): Max retries exceeded with url: /docs (Caused by NewConnectionError('<urllib3.connection.HTTPConnection object at 0x104e9abe0>: Failed to establish a new connection: [Errno 61] Connection refused'))",
      "response_size": 0
    },
    {
      "timestamp": "2025-06-30 14:28:13.079941",
      "response_time": 0.004400968551635742,
      "status_code": 0,
      "success": false,
      "error_message": "HTTPConnectionPool(host='localhost', port=80): Max retries exceeded with url: /api/ask (Caused by NewConnectionError('<urllib3.connection.HTTPConnection object at 0x104e9aad0>: Failed to establish a new connection: [Errno 61] Connection refused'))",
      "response_size": 0
    },
    {
      "timestamp": "2025-06-30 14:28:13.109314",
      "response_time": 0.0035948753356933594,
      "status_code": 0,
      "success": false,
      "error_message": "HTTPConnectionPool(host='localhost', port=80): Max retries exceeded with url: /api/ask (Caused by NewConnectionError('<urllib3.connection.HTTPConnection object at 0x104e9b570>: Failed to establish a new connection: [Errno 61] Connection refused'))",
      "response_size": 0
    },
    {
      "timestamp": "2025-06-30 14:28:13.138938",
      "response_time": 0.004358053207397461,
      "status_code": 0,
      "success": false,
      "error_message": "HTTPConnectionPool(host='localhost', port=80): Max retries exceeded with url: /api/ask (Caused by NewConnectionError('<urllib3.connection.HTTPConnection object at 0x104e9b680>: Failed to establish a new connection: [Errno 61] Connection refused'))",
      "response_size": 0
    },
    {
      "timestamp": "2025-06-30 14:28:13.562044",
      "response_time": 0.00457000732421875,
      "status_code": 0,
      "success": false,
      "error_message": "HTTPConnectionPool(host='localhost', port=80): Max retries exceeded with url: /api/ask (Caused by NewConnectionError('<urllib3.connection.HTTPConnection object at 0x104e9b240>: Failed to establish a new connection: [Errno 61] Connection refused'))",
      "response_size": 0
    },
    {
      "timestamp": "2025-06-30 14:28:13.589390",
      "response_time": 0.0019598007202148438,
      "status_code": 0,
      "success": false,
      "error_message": "HTTPConnectionPool(host='localhost', port=80): Max retries exceeded with url: /api/ask (Caused by NewConnectionError('<urllib3.connection.HTTPConnection object at 0x104e9bce0>: Failed to establish a new connection: [Errno 61] Connection refused'))",
      "response_size": 0
    },
    {
      "timestamp": "2025-06-30 14:28:13.616285",
      "response_time": 0.004041910171508789,
      "status_code": 0,
      "success": false,
      "error_message": "HTTPConnectionPool(host='localhost', port=80): Max retries exceeded with url: /api/ask (Caused by NewConnectionError('<urllib3.connection.HTTPConnection object at 0x104e9bf00>: Failed to establish a new connection: [Errno 61] Connection refused'))",
      "response_size": 0
    },
    {
      "timestamp": "2025-06-30 14:28:13.648413",
      "response_time": 0.0042188167572021484,
      "status_code": 0,
      "success": false,
      "error_message": "HTTPConnectionPool(host='localhost', port=80): Max retries exceeded with url: /api/ask (Caused by NewConnectionError('<urllib3.connection.HTTPConnection object at 0x104e9b9b0>: Failed to establish a new connection: [Errno 61] Connection refused'))",
      "response_size": 0
    },
    {
      "timestamp": "2025-06-30 14:28:14.071617",
      "response_time": 0.004448890686035156,
      "status_code": 0,
      "success": false,
      "error_message": "HTTPConnectionPool(host='localhost', port=80): Max retries exceeded with url: /docs (Caused by NewConnectionError('<urllib3.connection.HTTPConnection object at 0x104e9b8a0>: Failed to establish a new connection: [Errno 61] Connection refused'))",
      "response_size": 0
    },
    {
      "timestamp": "2025-06-30 14:28:14.096457",
      "response_time": 0.010601043701171875,
      "status_code": 0,
      "success": false,
      "error_message": "HTTPConnectionPool(host='localhost', port=80): Max retries exceeded with url: /api/ask (Caused by NewConnectionError('<urllib3.connection.HTTPConnection object at 0x104e9b8a0>: Failed to establish a new connection: [Errno 61] Connection refused'))",
      "response_size": 0
    },
    {
      "timestamp": "2025-06-30 14:28:14.124154",
      "response_time": 0.0021958351135253906,
      "status_code": 0,
      "success": false,
      "error_message": "HTTPConnectionPool(host='localhost', port=80): Max retries exceeded with url: /api/ask (Caused by NewConnectionError('<urllib3.connection.HTTPConnection object at 0x104e99f20>: Failed to establish a new connection: [Errno 61] Connection refused'))",
      "response_size": 0
    },
    {
      "timestamp": "2025-06-30 14:28:14.155849",
      "response_time": 0.0038390159606933594,
      "status_code": 0,
      "success": false,
      "error_message": "HTTPConnectionPool(host='localhost', port=80): Max retries exceeded with url: /api/ask (Caused by NewConnectionError('<urllib3.connection.HTTPConnection object at 0x104e9bac0>: Failed to establish a new connection: [Errno 61] Connection refused'))",
      "response_size": 0
    },
    {
      "timestamp": "2025-06-30 14:28:14.581197",
      "response_time": 0.0043942928314208984,
      "status_code": 0,
      "success": false,
      "error_message": "HTTPConnectionPool(host='localhost', port=80): Max retries exceeded with url: /api/ask (Caused by NewConnectionError('<urllib3.connection.HTTPConnection object at 0x104e9bbd0>: Failed to establish a new connection: [Errno 61] Connection refused'))",
      "response_size": 0
    },
    {
      "timestamp": "2025-06-30 14:28:14.612147",
      "response_time": 0.004658937454223633,
      "status_code": 0,
      "success": false,
      "error_message": "HTTPConnectionPool(host='localhost', port=80): Max retries exceeded with url: /api/ask (Caused by NewConnectionError('<urllib3.connection.HTTPConnection object at 0x104e9bdf0>: Failed to establish a new connection: [Errno 61] Connection refused'))",
      "response_size": 0
    },
    {
      "timestamp": "2025-06-30 14:28:14.631439",
      "response_time": 0.003648996353149414,
      "status_code": 0,
      "success": false,
      "error_message": "HTTPConnectionPool(host='localhost', port=80): Max retries exceeded with url: /api/ask (Caused by NewConnectionError('<urllib3.connection.HTTPConnection object at 0x104e9b130>: Failed to establish a new connection: [Errno 61] Connection refused'))",
      "response_size": 0
    },
    {
      "timestamp": "2025-06-30 14:28:15.088292",
      "response_time": 0.004488945007324219,
      "status_code": 0,
      "success": false,
      "error_message": "HTTPConnectionPool(host='localhost', port=80): Max retries exceeded with url: /health (Caused by NewConnectionError('<urllib3.connection.HTTPConnection object at 0x104e9b460>: Failed to establish a new connection: [Errno 61] Connection refused'))",
      "response_size": 0
    },
    {
      "timestamp": "2025-06-30 14:28:15.117013",
      "response_time": 0.0037670135498046875,
      "status_code": 0,
      "success": false,
      "error_message": "HTTPConnectionPool(host='localhost', port=80): Max retries exceeded with url: /api/ask (Caused by NewConnectionError('<urllib3.connection.HTTPConnection object at 0x104e9b790>: Failed to establish a new connection: [Errno 61] Connection refused'))",
      "response_size": 0
    },
    {
      "timestamp": "2025-06-30 14:28:15.139192",
      "response_time": 0.004340171813964844,
      "status_code": 0,
      "success": false,
      "error_message": "HTTPConnectionPool(host='localhost', port=80): Max retries exceeded with url: /api/ask (Caused by NewConnectionError('<urllib3.connection.HTTPConnection object at 0x104e9af10>: Failed to establish a new connection: [Errno 61] Connection refused'))",
      "response_size": 0
    },
    {
      "timestamp": "2025-06-30 14:28:15.594513",
      "response_time": 0.0043299198150634766,
      "status_code": 0,
      "success": false,
      "error_message": "HTTPConnectionPool(host='localhost', port=80): Max retries exceeded with url: /api/ask (Caused by NewConnectionError('<urllib3.connection.HTTPConnection object at 0x104e9acf0>: Failed to establish a new connection: [Errno 61] Connection refused'))",
      "response_size": 0
    },
    {
      "timestamp": "2025-06-30 14:28:15.623532",
      "response_time": 0.003589153289794922,
      "status_code": 0,
      "success": false,
      "error_message": "HTTPConnectionPool(host='localhost', port=80): Max retries exceeded with url: /api/ask (Caused by NewConnectionError('<urllib3.connection.HTTPConnection object at 0x104e9a7a0>: Failed to establish a new connection: [Errno 61] Connection refused'))",
      "response_size": 0
    },
    {
      "timestamp": "2025-06-30 14:28:15.643946",
      "response_time": 0.0039310455322265625,
      "status_code": 0,
      "success": false,
      "error_message": "HTTPConnectionPool(host='localhost', port=80): Max retries exceeded with url: /api/ask (Caused by NewConnectionError('<urllib3.connection.HTTPConnection object at 0x104e9a9c0>: Failed to establish a new connection: [Errno 61] Connection refused'))",
      "response_size": 0
    },
    {
      "timestamp": "2025-06-30 14:28:16.101463",
      "response_time": 0.004364967346191406,
      "status_code": 0,
      "success": false,
      "error_message": "HTTPConnectionPool(host='localhost', port=80): Max retries exceeded with url: /api/ask (Caused by NewConnectionError('<urllib3.connection.HTTPConnection object at 0x104e9a580>: Failed to establish a new connection: [Errno 61] Connection refused'))",
      "response_size": 0
    },
    {
      "timestamp": "2025-06-30 14:28:16.130334",
      "response_time": 0.0033059120178222656,
      "status_code": 0,
      "success": false,
      "error_message": "HTTPConnectionPool(host='localhost', port=80): Max retries exceeded with url: /metrics (Caused by NewConnectionError('<urllib3.connection.HTTPConnection object at 0x104e9a470>: Failed to establish a new connection: [Errno 61] Connection refused'))",
      "response_size": 0
    },
    {
      "timestamp": "2025-06-30 14:28:16.148854",
      "response_time": 0.0036559104919433594,
      "status_code": 0,
      "success": false,
      "error_message": "HTTPConnectionPool(host='localhost', port=80): Max retries exceeded with url: /api/ask (Caused by NewConnectionError('<urllib3.connection.HTTPConnection object at 0x104e99260>: Failed to establish a new connection: [Errno 61] Connection refused'))",
      "response_size": 0
    },
    {
      "timestamp": "2025-06-30 14:28:16.607101",
      "response_time": 0.004029989242553711,
      "status_code": 0,
      "success": false,
      "error_message": "HTTPConnectionPool(host='localhost', port=80): Max retries exceeded with url: /api/ask (Caused by NewConnectionError('<urllib3.connection.HTTPConnection object at 0x104e98e20>: Failed to establish a new connection: [Errno 61] Connection refused'))",
      "response_size": 0
    },
    {
      "timestamp": "2025-06-30 14:28:16.638263",
      "response_time": 0.0059850215911865234,
      "status_code": 0,
      "success": false,
      "error_message": "HTTPConnectionPool(host='localhost', port=80): Max retries exceeded with url: /api/ask (Caused by NewConnectionError('<urllib3.connection.HTTPConnection object at 0x104e98e20>: Failed to establish a new connection: [Errno 61] Connection refused'))",
      "response_size": 0
    },
    {
      "timestamp": "2025-06-30 14:28:17.116238",
      "response_time": 0.003426074981689453,
      "status_code": 0,
      "success": false,
      "error_message": "HTTPConnectionPool(host='localhost', port=80): Max retries exceeded with url: /metrics (Caused by NewConnectionError('<urllib3.connection.HTTPConnection object at 0x104e9b350>: Failed to establish a new connection: [Errno 61] Connection refused'))",
      "response_size": 0
    },
    {
      "timestamp": "2025-06-30 14:28:17.148908",
      "response_time": 0.004189252853393555,
      "status_code": 0,
      "success": false,
      "error_message": "HTTPConnectionPool(host='localhost', port=80): Max retries exceeded with url: /api/ask (Caused by NewConnectionError('<urllib3.connection.HTTPConnection object at 0x104e9a030>: Failed to establish a new connection: [Errno 61] Connection refused'))",
      "response_size": 0
    },
    {
      "timestamp": "2025-06-30 14:28:17.623757",
      "response_time": 0.0027310848236083984,
      "status_code": 0,
      "success": false,
      "error_message": "HTTPConnectionPool(host='localhost', port=80): Max retries exceeded with url: /health (Caused by NewConnectionError('<urllib3.connection.HTTPConnection object at 0x104e9b020>: Failed to establish a new connection: [Errno 61] Connection refused'))",
      "response_size": 0
    },
    {
      "timestamp": "2025-06-30 14:28:17.655827",
      "response_time": 0.0036399364471435547,
      "status_code": 0,
      "success": false,
      "error_message": "HTTPConnectionPool(host='localhost', port=80): Max retries exceeded with url: /api/ask (Caused by NewConnectionError('<urllib3.connection.HTTPConnection object at 0x104e9a140>: Failed to establish a new connection: [Errno 61] Connection refused'))",
      "response_size": 0
    },
    {
      "timestamp": "2025-06-30 14:28:18.131720",
      "response_time": 0.003835916519165039,
      "status_code": 0,
      "success": false,
      "error_message": "HTTPConnectionPool(host='localhost', port=80): Max retries exceeded with url: /api/ask (Caused by NewConnectionError('<urllib3.connection.HTTPConnection object at 0x104e9a250>: Failed to establish a new connection: [Errno 61] Connection refused'))",
      "response_size": 0
    },
    {
      "timestamp": "2025-06-30 14:28:18.163669",
      "response_time": 0.001953125,
      "status_code": 0,
      "success": false,
      "error_message": "HTTPConnectionPool(host='localhost', port=80): Max retries exceeded with url: /docs (Caused by NewConnectionError('<urllib3.connection.HTTPConnection object at 0x104e9a360>: Failed to establish a new connection: [Errno 61] Connection refused'))",
      "response_size": 0
    },
    {
      "timestamp": "2025-06-30 14:28:18.640680",
      "response_time": 0.004473209381103516,
      "status_code": 0,
      "success": false,
      "error_message": "HTTPConnectionPool(host='localhost', port=80): Max retries exceeded with url: /api/ask (Caused by NewConnectionError('<urllib3.connection.HTTPConnection object at 0x104e9a690>: Failed to establish a new connection: [Errno 61] Connection refused'))",
      "response_size": 0
    },
    {
      "timestamp": "2025-06-30 14:28:19.148735",
      "response_time": 0.0040509700775146484,
      "status_code": 0,
      "success": false,
      "error_message": "HTTPConnectionPool(host='localhost', port=80): Max retries exceeded with url: /api/ask (Caused by NewConnectionError('<urllib3.connection.HTTPConnection object at 0x104e9a8b0>: Failed to establish a new connection: [Errno 61] Connection refused'))",
      "response_size": 0
    },
    {
      "timestamp": "2025-06-30 14:28:19.654990",
      "response_time": 0.0026831626892089844,
      "status_code": 0,
      "success": false,
      "error_message": "HTTPConnectionPool(host='localhost', port=80): Max retries exceeded with url: /api/ask (Caused by NewConnectionError('<urllib3.connection.HTTPConnection object at 0x104e9abe0>: Failed to establish a new connection: [Errno 61] Connection refused'))",
      "response_size": 0
    },
    {
      "timestamp": "2025-06-30 14:28:20.158927",
      "response_time": 0.003384113311767578,
      "status_code": 0,
      "success": false,
      "error_message": "HTTPConnectionPool(host='localhost', port=80): Max retries exceeded with url: /api/ask (Caused by NewConnectionError('<urllib3.connection.HTTPConnection object at 0x104e9aad0>: Failed to establish a new connection: [Errno 61] Connection refused'))",
      "response_size": 0
    }
  ]
}