2025-06-19 17:51:57,801 | pynucleus.rag.vector_store | ERROR | vector_store.py:612 | Failed to initialize ChromaDB: An instance of Chroma already exists for data/03_intermediate/vector_db with different settings
2025-06-19 17:51:57,801 | pynucleus.pipeline.pipeline_rag | WARNING | pipeline_rag.py:40 | Vector store (chroma) not fully loaded - will use fallback mode
2025-06-19 17:51:57,822 | pynucleus.rag.vector_store | INFO | vector_store.py:362 | No existing FAISS directories found
2025-06-19 17:51:57,822 | pynucleus.pipeline.pipeline_utils | INFO | pipeline_utils.py:42 | Pipeline components initialized successfully
2025-06-19 17:51:57,822 | pynucleus.pipeline.pipeline_utils | WARNING | pipeline_utils.py:46 | FAISS vector store not loaded - using fallback mode
2025-06-19 17:51:57,823 | pynucleus.rag.vector_store | ERROR | vector_store.py:612 | Failed to initialize ChromaDB: An instance of Chroma already exists for data/03_intermediate/vector_db with different settings
2025-06-19 17:51:57,823 | pynucleus.pipeline.pipeline_rag | WARNING | pipeline_rag.py:40 | Vector store (chroma) not fully loaded - will use fallback mode
2025-06-19 17:51:57,824 | pynucleus.integration.llm_output_generator | INFO | llm_output_generator.py:21 | Using direct content generation (templates migrated to DSPy)
2025-06-19 17:51:57,824 | pynucleus.rag.vector_store | ERROR | vector_store.py:612 | Failed to initialize ChromaDB: An instance of Chroma already exists for data/03_intermediate/vector_db with different settings
2025-06-19 17:52:00,069 | urllib3.connectionpool | WARNING | connectionpool.py:868 | Retrying (Retry(total=1, connect=1, read=2, redirect=None, status=None)) after connection broken by 'NameResolutionError("<urllib3.connection.HTTPSConnection object at 0x425b487d0>: Failed to resolve 'us.i.posthog.com' ([Errno 8] nodename nor servname provided, or not known)")': /batch/
2025-06-19 17:52:00,070 | urllib3.connectionpool | WARNING | connectionpool.py:868 | Retrying (Retry(total=0, connect=0, read=2, redirect=None, status=None)) after connection broken by 'NameResolutionError("<urllib3.connection.HTTPSConnection object at 0x425b48a50>: Failed to resolve 'us.i.posthog.com' ([Errno 8] nodename nor servname provided, or not known)")': /batch/
2025-06-19 17:52:00,072 | backoff | ERROR | _common.py:120 | Giving up send_request(...) after 4 tries (requests.exceptions.ConnectionError: HTTPSConnectionPool(host='us.i.posthog.com', port=443): Max retries exceeded with url: /batch/ (Caused by NameResolutionError("<urllib3.connection.HTTPSConnection object at 0x425b48cd0>: Failed to resolve 'us.i.posthog.com' ([Errno 8] nodename nor servname provided, or not known)")))
2025-06-19 17:52:00,072 | posthog | ERROR | consumer.py:84 | error uploading: HTTPSConnectionPool(host='us.i.posthog.com', port=443): Max retries exceeded with url: /batch/ (Caused by NameResolutionError("<urllib3.connection.HTTPSConnection object at 0x425b48cd0>: Failed to resolve 'us.i.posthog.com' ([Errno 8] nodename nor servname provided, or not known)"))
