2025-06-19 16:39:35,432 | __main__ | INFO | run_pipeline.py:319 | üöÄ Starting document ingestion
2025-06-19 16:39:35,432 | __main__ | INFO | run_pipeline.py:320 | üìÅ Source directory: data/01_raw
2025-06-19 16:39:35,432 | __main__ | INFO | run_pipeline.py:321 | üìÅ Output directory: data/03_intermediate
2025-06-19 16:39:35,432 | __main__ | INFO | run_pipeline.py:336 | üîß Using vector store backend: chroma
2025-06-19 16:39:35,433 | pynucleus.rag.rag_core | INFO | rag_core.py:34 | RAG Core components initialized successfully
2025-06-19 16:39:35,433 | __main__ | INFO | run_pipeline.py:348 | üîÑ Processing documents...
2025-06-19 16:39:38,936 | datasets | INFO | config.py:54 | PyTorch version 2.7.1 available.
2025-06-19 16:39:39,282 | chromadb.telemetry.product.posthog | INFO | posthog.py:22 | Anonymized telemetry enabled. See                     https://docs.trychroma.com/telemetry for more information.
2025-06-19 16:39:39,316 | chromadb.config | DEBUG | config.py:359 | Starting component System
2025-06-19 16:39:39,317 | chromadb.config | DEBUG | config.py:359 | Starting component Posthog
2025-06-19 16:39:39,372 | sentence_transformers.SentenceTransformer | INFO | SentenceTransformer.py:211 | Use pytorch device_name: mps
2025-06-19 16:39:39,372 | sentence_transformers.SentenceTransformer | INFO | SentenceTransformer.py:219 | Load pretrained SentenceTransformer: all-MiniLM-L6-v2
2025-06-19 16:39:39,373 | urllib3.connectionpool | DEBUG | connectionpool.py:1049 | Starting new HTTPS connection (1): huggingface.co:443
2025-06-19 16:39:39,564 | urllib3.connectionpool | DEBUG | connectionpool.py:544 | https://huggingface.co:443 "HEAD /sentence-transformers/all-MiniLM-L6-v2/resolve/main/modules.json HTTP/1.1" 200 0
2025-06-19 16:39:39,614 | urllib3.connectionpool | DEBUG | connectionpool.py:544 | https://huggingface.co:443 "HEAD /sentence-transformers/all-MiniLM-L6-v2/resolve/main/config_sentence_transformers.json HTTP/1.1" 200 0
2025-06-19 16:39:39,662 | urllib3.connectionpool | DEBUG | connectionpool.py:544 | https://huggingface.co:443 "HEAD /sentence-transformers/all-MiniLM-L6-v2/resolve/main/README.md HTTP/1.1" 200 0
2025-06-19 16:39:39,709 | urllib3.connectionpool | DEBUG | connectionpool.py:544 | https://huggingface.co:443 "HEAD /sentence-transformers/all-MiniLM-L6-v2/resolve/main/modules.json HTTP/1.1" 200 0
2025-06-19 16:39:39,754 | urllib3.connectionpool | DEBUG | connectionpool.py:544 | https://huggingface.co:443 "HEAD /sentence-transformers/all-MiniLM-L6-v2/resolve/main/sentence_bert_config.json HTTP/1.1" 200 0
2025-06-19 16:39:39,802 | urllib3.connectionpool | DEBUG | connectionpool.py:544 | https://huggingface.co:443 "HEAD /sentence-transformers/all-MiniLM-L6-v2/resolve/main/adapter_config.json HTTP/1.1" 404 0
2025-06-19 16:39:39,853 | urllib3.connectionpool | DEBUG | connectionpool.py:1049 | Starting new HTTPS connection (1): us.i.posthog.com:443
2025-06-19 16:39:39,863 | urllib3.util.retry | DEBUG | retry.py:521 | Incremented Retry for (url='/batch/'): Retry(total=1, connect=1, read=2, redirect=None, status=None)
2025-06-19 16:39:39,863 | urllib3.connectionpool | WARNING | connectionpool.py:868 | Retrying (Retry(total=1, connect=1, read=2, redirect=None, status=None)) after connection broken by 'NameResolutionError("<urllib3.connection.HTTPSConnection object at 0x14d98a850>: Failed to resolve 'us.i.posthog.com' ([Errno 8] nodename nor servname provided, or not known)")': /batch/
2025-06-19 16:39:39,863 | urllib3.connectionpool | DEBUG | connectionpool.py:1049 | Starting new HTTPS connection (2): us.i.posthog.com:443
2025-06-19 16:39:39,865 | urllib3.util.retry | DEBUG | retry.py:521 | Incremented Retry for (url='/batch/'): Retry(total=0, connect=0, read=2, redirect=None, status=None)
2025-06-19 16:39:39,865 | urllib3.connectionpool | WARNING | connectionpool.py:868 | Retrying (Retry(total=0, connect=0, read=2, redirect=None, status=None)) after connection broken by 'NameResolutionError("<urllib3.connection.HTTPSConnection object at 0x14d98aad0>: Failed to resolve 'us.i.posthog.com' ([Errno 8] nodename nor servname provided, or not known)")': /batch/
2025-06-19 16:39:39,865 | urllib3.connectionpool | DEBUG | connectionpool.py:1049 | Starting new HTTPS connection (3): us.i.posthog.com:443
2025-06-19 16:39:39,870 | backoff | INFO | _common.py:105 | Backing off send_request(...) for 1.0s (requests.exceptions.ConnectionError: HTTPSConnectionPool(host='us.i.posthog.com', port=443): Max retries exceeded with url: /batch/ (Caused by NameResolutionError("<urllib3.connection.HTTPSConnection object at 0x14d98ad50>: Failed to resolve 'us.i.posthog.com' ([Errno 8] nodename nor servname provided, or not known)")))
2025-06-19 16:39:39,897 | urllib3.connectionpool | DEBUG | connectionpool.py:544 | https://huggingface.co:443 "HEAD /sentence-transformers/all-MiniLM-L6-v2/resolve/main/config.json HTTP/1.1" 200 0
2025-06-19 16:39:40,325 | urllib3.connectionpool | DEBUG | connectionpool.py:544 | https://huggingface.co:443 "HEAD /sentence-transformers/all-MiniLM-L6-v2/resolve/main/tokenizer_config.json HTTP/1.1" 200 0
2025-06-19 16:39:40,374 | urllib3.connectionpool | DEBUG | connectionpool.py:544 | https://huggingface.co:443 "GET /api/models/sentence-transformers/all-MiniLM-L6-v2/tree/main/additional_chat_templates?recursive=False&expand=False HTTP/1.1" 404 64
2025-06-19 16:39:40,460 | urllib3.connectionpool | DEBUG | connectionpool.py:544 | https://huggingface.co:443 "GET /api/models/sentence-transformers/all-MiniLM-L6-v2/revision/main HTTP/1.1" 200 6834
2025-06-19 16:39:40,525 | urllib3.connectionpool | DEBUG | connectionpool.py:544 | https://huggingface.co:443 "GET /api/models/sentence-transformers/all-MiniLM-L6-v2 HTTP/1.1" 200 6834
2025-06-19 16:39:40,833 | urllib3.connectionpool | DEBUG | connectionpool.py:1049 | Starting new HTTPS connection (4): us.i.posthog.com:443
2025-06-19 16:39:40,834 | urllib3.util.retry | DEBUG | retry.py:521 | Incremented Retry for (url='/batch/'): Retry(total=1, connect=1, read=2, redirect=None, status=None)
2025-06-19 16:39:40,835 | urllib3.connectionpool | WARNING | connectionpool.py:868 | Retrying (Retry(total=1, connect=1, read=2, redirect=None, status=None)) after connection broken by 'NameResolutionError("<urllib3.connection.HTTPSConnection object at 0x15045e350>: Failed to resolve 'us.i.posthog.com' ([Errno 8] nodename nor servname provided, or not known)")': /batch/
2025-06-19 16:39:40,835 | urllib3.connectionpool | DEBUG | connectionpool.py:1049 | Starting new HTTPS connection (5): us.i.posthog.com:443
2025-06-19 16:39:40,835 | urllib3.util.retry | DEBUG | retry.py:521 | Incremented Retry for (url='/batch/'): Retry(total=0, connect=0, read=2, redirect=None, status=None)
2025-06-19 16:39:40,835 | urllib3.connectionpool | WARNING | connectionpool.py:868 | Retrying (Retry(total=0, connect=0, read=2, redirect=None, status=None)) after connection broken by 'NameResolutionError("<urllib3.connection.HTTPSConnection object at 0x15045e5d0>: Failed to resolve 'us.i.posthog.com' ([Errno 8] nodename nor servname provided, or not known)")': /batch/
2025-06-19 16:39:40,835 | urllib3.connectionpool | DEBUG | connectionpool.py:1049 | Starting new HTTPS connection (6): us.i.posthog.com:443
2025-06-19 16:39:40,836 | backoff | INFO | _common.py:105 | Backing off send_request(...) for 1.4s (requests.exceptions.ConnectionError: HTTPSConnectionPool(host='us.i.posthog.com', port=443): Max retries exceeded with url: /batch/ (Caused by NameResolutionError("<urllib3.connection.HTTPSConnection object at 0x15045e850>: Failed to resolve 'us.i.posthog.com' ([Errno 8] nodename nor servname provided, or not known)")))
2025-06-19 16:39:42,560 | urllib3.connectionpool | DEBUG | connectionpool.py:1049 | Starting new HTTPS connection (7): us.i.posthog.com:443
2025-06-19 16:39:42,561 | urllib3.util.retry | DEBUG | retry.py:521 | Incremented Retry for (url='/batch/'): Retry(total=1, connect=1, read=2, redirect=None, status=None)
2025-06-19 16:39:42,562 | urllib3.connectionpool | WARNING | connectionpool.py:868 | Retrying (Retry(total=1, connect=1, read=2, redirect=None, status=None)) after connection broken by 'NameResolutionError("<urllib3.connection.HTTPSConnection object at 0x15045f250>: Failed to resolve 'us.i.posthog.com' ([Errno 8] nodename nor servname provided, or not known)")': /batch/
2025-06-19 16:39:42,562 | urllib3.connectionpool | DEBUG | connectionpool.py:1049 | Starting new HTTPS connection (8): us.i.posthog.com:443
2025-06-19 16:39:42,562 | urllib3.util.retry | DEBUG | retry.py:521 | Incremented Retry for (url='/batch/'): Retry(total=0, connect=0, read=2, redirect=None, status=None)
2025-06-19 16:39:42,562 | urllib3.connectionpool | WARNING | connectionpool.py:868 | Retrying (Retry(total=0, connect=0, read=2, redirect=None, status=None)) after connection broken by 'NameResolutionError("<urllib3.connection.HTTPSConnection object at 0x15045f9d0>: Failed to resolve 'us.i.posthog.com' ([Errno 8] nodename nor servname provided, or not known)")': /batch/
2025-06-19 16:39:42,562 | urllib3.connectionpool | DEBUG | connectionpool.py:1049 | Starting new HTTPS connection (9): us.i.posthog.com:443
2025-06-19 16:39:42,564 | backoff | INFO | _common.py:105 | Backing off send_request(...) for 3.0s (requests.exceptions.ConnectionError: HTTPSConnectionPool(host='us.i.posthog.com', port=443): Max retries exceeded with url: /batch/ (Caused by NameResolutionError("<urllib3.connection.HTTPSConnection object at 0x15045fc50>: Failed to resolve 'us.i.posthog.com' ([Errno 8] nodename nor servname provided, or not known)")))
2025-06-19 16:39:45,616 | urllib3.connectionpool | DEBUG | connectionpool.py:1049 | Starting new HTTPS connection (10): us.i.posthog.com:443
2025-06-19 16:39:45,633 | urllib3.util.retry | DEBUG | retry.py:521 | Incremented Retry for (url='/batch/'): Retry(total=1, connect=1, read=2, redirect=None, status=None)
2025-06-19 16:39:45,634 | urllib3.connectionpool | WARNING | connectionpool.py:868 | Retrying (Retry(total=1, connect=1, read=2, redirect=None, status=None)) after connection broken by 'NameResolutionError("<urllib3.connection.HTTPSConnection object at 0x179ae8690>: Failed to resolve 'us.i.posthog.com' ([Errno 8] nodename nor servname provided, or not known)")': /batch/
2025-06-19 16:39:45,641 | urllib3.connectionpool | DEBUG | connectionpool.py:1049 | Starting new HTTPS connection (11): us.i.posthog.com:443
2025-06-19 16:39:45,655 | urllib3.util.retry | DEBUG | retry.py:521 | Incremented Retry for (url='/batch/'): Retry(total=0, connect=0, read=2, redirect=None, status=None)
2025-06-19 16:39:45,663 | urllib3.connectionpool | WARNING | connectionpool.py:868 | Retrying (Retry(total=0, connect=0, read=2, redirect=None, status=None)) after connection broken by 'NameResolutionError("<urllib3.connection.HTTPSConnection object at 0x179ae8910>: Failed to resolve 'us.i.posthog.com' ([Errno 8] nodename nor servname provided, or not known)")': /batch/
2025-06-19 16:39:45,664 | urllib3.connectionpool | DEBUG | connectionpool.py:1049 | Starting new HTTPS connection (12): us.i.posthog.com:443
2025-06-19 16:39:45,690 | backoff | ERROR | _common.py:120 | Giving up send_request(...) after 4 tries (requests.exceptions.ConnectionError: HTTPSConnectionPool(host='us.i.posthog.com', port=443): Max retries exceeded with url: /batch/ (Caused by NameResolutionError("<urllib3.connection.HTTPSConnection object at 0x179ae8b90>: Failed to resolve 'us.i.posthog.com' ([Errno 8] nodename nor servname provided, or not known)")))
2025-06-19 16:39:46,227 | urllib3.connectionpool | DEBUG | connectionpool.py:1049 | Starting new HTTPS connection (13): us.i.posthog.com:443
2025-06-19 16:39:46,239 | urllib3.util.retry | DEBUG | retry.py:521 | Incremented Retry for (url='/batch/'): Retry(total=1, connect=1, read=2, redirect=None, status=None)
2025-06-19 16:39:46,246 | urllib3.connectionpool | WARNING | connectionpool.py:868 | Retrying (Retry(total=1, connect=1, read=2, redirect=None, status=None)) after connection broken by 'NameResolutionError("<urllib3.connection.HTTPSConnection object at 0x179ae9090>: Failed to resolve 'us.i.posthog.com' ([Errno 8] nodename nor servname provided, or not known)")': /batch/
2025-06-19 16:39:46,247 | urllib3.connectionpool | DEBUG | connectionpool.py:1049 | Starting new HTTPS connection (14): us.i.posthog.com:443
2025-06-19 16:39:46,254 | urllib3.util.retry | DEBUG | retry.py:521 | Incremented Retry for (url='/batch/'): Retry(total=0, connect=0, read=2, redirect=None, status=None)
2025-06-19 16:39:46,259 | urllib3.connectionpool | WARNING | connectionpool.py:868 | Retrying (Retry(total=0, connect=0, read=2, redirect=None, status=None)) after connection broken by 'NameResolutionError("<urllib3.connection.HTTPSConnection object at 0x179ae9450>: Failed to resolve 'us.i.posthog.com' ([Errno 8] nodename nor servname provided, or not known)")': /batch/
2025-06-19 16:39:46,265 | urllib3.connectionpool | DEBUG | connectionpool.py:1049 | Starting new HTTPS connection (15): us.i.posthog.com:443
2025-06-19 16:39:46,294 | backoff | INFO | _common.py:105 | Backing off send_request(...) for 0.3s (requests.exceptions.ConnectionError: HTTPSConnectionPool(host='us.i.posthog.com', port=443): Max retries exceeded with url: /batch/ (Caused by NameResolutionError("<urllib3.connection.HTTPSConnection object at 0x179ae96d0>: Failed to resolve 'us.i.posthog.com' ([Errno 8] nodename nor servname provided, or not known)")))
2025-06-19 16:39:46,628 | urllib3.connectionpool | DEBUG | connectionpool.py:1049 | Starting new HTTPS connection (16): us.i.posthog.com:443
2025-06-19 16:39:46,641 | urllib3.util.retry | DEBUG | retry.py:521 | Incremented Retry for (url='/batch/'): Retry(total=1, connect=1, read=2, redirect=None, status=None)
2025-06-19 16:39:46,643 | urllib3.connectionpool | WARNING | connectionpool.py:868 | Retrying (Retry(total=1, connect=1, read=2, redirect=None, status=None)) after connection broken by 'NameResolutionError("<urllib3.connection.HTTPSConnection object at 0x15045e710>: Failed to resolve 'us.i.posthog.com' ([Errno 8] nodename nor servname provided, or not known)")': /batch/
2025-06-19 16:39:46,643 | urllib3.connectionpool | DEBUG | connectionpool.py:1049 | Starting new HTTPS connection (17): us.i.posthog.com:443
2025-06-19 16:39:46,650 | urllib3.util.retry | DEBUG | retry.py:521 | Incremented Retry for (url='/batch/'): Retry(total=0, connect=0, read=2, redirect=None, status=None)
2025-06-19 16:39:46,653 | urllib3.connectionpool | WARNING | connectionpool.py:868 | Retrying (Retry(total=0, connect=0, read=2, redirect=None, status=None)) after connection broken by 'NameResolutionError("<urllib3.connection.HTTPSConnection object at 0x15045fb10>: Failed to resolve 'us.i.posthog.com' ([Errno 8] nodename nor servname provided, or not known)")': /batch/
2025-06-19 16:39:46,653 | urllib3.connectionpool | DEBUG | connectionpool.py:1049 | Starting new HTTPS connection (18): us.i.posthog.com:443
2025-06-19 16:39:46,665 | backoff | INFO | _common.py:105 | Backing off send_request(...) for 0.8s (requests.exceptions.ConnectionError: HTTPSConnectionPool(host='us.i.posthog.com', port=443): Max retries exceeded with url: /batch/ (Caused by NameResolutionError("<urllib3.connection.HTTPSConnection object at 0x15045f610>: Failed to resolve 'us.i.posthog.com' ([Errno 8] nodename nor servname provided, or not known)")))
2025-06-19 16:39:47,467 | urllib3.connectionpool | DEBUG | connectionpool.py:1049 | Starting new HTTPS connection (19): us.i.posthog.com:443
2025-06-19 16:39:47,469 | urllib3.util.retry | DEBUG | retry.py:521 | Incremented Retry for (url='/batch/'): Retry(total=1, connect=1, read=2, redirect=None, status=None)
2025-06-19 16:39:47,469 | urllib3.connectionpool | WARNING | connectionpool.py:868 | Retrying (Retry(total=1, connect=1, read=2, redirect=None, status=None)) after connection broken by 'NameResolutionError("<urllib3.connection.HTTPSConnection object at 0x179ae8a50>: Failed to resolve 'us.i.posthog.com' ([Errno 8] nodename nor servname provided, or not known)")': /batch/
2025-06-19 16:39:47,469 | urllib3.connectionpool | DEBUG | connectionpool.py:1049 | Starting new HTTPS connection (20): us.i.posthog.com:443
2025-06-19 16:39:47,469 | urllib3.util.retry | DEBUG | retry.py:521 | Incremented Retry for (url='/batch/'): Retry(total=0, connect=0, read=2, redirect=None, status=None)
2025-06-19 16:39:47,469 | urllib3.connectionpool | WARNING | connectionpool.py:868 | Retrying (Retry(total=0, connect=0, read=2, redirect=None, status=None)) after connection broken by 'NameResolutionError("<urllib3.connection.HTTPSConnection object at 0x179ae9d10>: Failed to resolve 'us.i.posthog.com' ([Errno 8] nodename nor servname provided, or not known)")': /batch/
2025-06-19 16:39:47,470 | urllib3.connectionpool | DEBUG | connectionpool.py:1049 | Starting new HTTPS connection (21): us.i.posthog.com:443
2025-06-19 16:39:47,470 | backoff | INFO | _common.py:105 | Backing off send_request(...) for 3.8s (requests.exceptions.ConnectionError: HTTPSConnectionPool(host='us.i.posthog.com', port=443): Max retries exceeded with url: /batch/ (Caused by NameResolutionError("<urllib3.connection.HTTPSConnection object at 0x179ae9f90>: Failed to resolve 'us.i.posthog.com' ([Errno 8] nodename nor servname provided, or not known)")))
2025-06-19 16:39:51,255 | urllib3.connectionpool | DEBUG | connectionpool.py:1049 | Starting new HTTPS connection (22): us.i.posthog.com:443
2025-06-19 16:39:51,256 | urllib3.util.retry | DEBUG | retry.py:521 | Incremented Retry for (url='/batch/'): Retry(total=1, connect=1, read=2, redirect=None, status=None)
2025-06-19 16:39:51,256 | urllib3.connectionpool | WARNING | connectionpool.py:868 | Retrying (Retry(total=1, connect=1, read=2, redirect=None, status=None)) after connection broken by 'NameResolutionError("<urllib3.connection.HTTPSConnection object at 0x179aea5d0>: Failed to resolve 'us.i.posthog.com' ([Errno 8] nodename nor servname provided, or not known)")': /batch/
2025-06-19 16:39:51,256 | urllib3.connectionpool | DEBUG | connectionpool.py:1049 | Starting new HTTPS connection (23): us.i.posthog.com:443
2025-06-19 16:39:51,257 | urllib3.util.retry | DEBUG | retry.py:521 | Incremented Retry for (url='/batch/'): Retry(total=0, connect=0, read=2, redirect=None, status=None)
2025-06-19 16:39:51,257 | urllib3.connectionpool | WARNING | connectionpool.py:868 | Retrying (Retry(total=0, connect=0, read=2, redirect=None, status=None)) after connection broken by 'NameResolutionError("<urllib3.connection.HTTPSConnection object at 0x179aea850>: Failed to resolve 'us.i.posthog.com' ([Errno 8] nodename nor servname provided, or not known)")': /batch/
2025-06-19 16:39:51,257 | urllib3.connectionpool | DEBUG | connectionpool.py:1049 | Starting new HTTPS connection (24): us.i.posthog.com:443
2025-06-19 16:39:51,258 | backoff | ERROR | _common.py:120 | Giving up send_request(...) after 4 tries (requests.exceptions.ConnectionError: HTTPSConnectionPool(host='us.i.posthog.com', port=443): Max retries exceeded with url: /batch/ (Caused by NameResolutionError("<urllib3.connection.HTTPSConnection object at 0x179aeaad0>: Failed to resolve 'us.i.posthog.com' ([Errno 8] nodename nor servname provided, or not known)")))
2025-06-19 16:41:46,033 | urllib3.connectionpool | DEBUG | connectionpool.py:1049 | Starting new HTTPS connection (25): us.i.posthog.com:443
2025-06-19 16:41:46,041 | urllib3.util.retry | DEBUG | retry.py:521 | Incremented Retry for (url='/batch/'): Retry(total=1, connect=1, read=2, redirect=None, status=None)
2025-06-19 16:41:46,041 | urllib3.connectionpool | WARNING | connectionpool.py:868 | Retrying (Retry(total=1, connect=1, read=2, redirect=None, status=None)) after connection broken by 'NameResolutionError("<urllib3.connection.HTTPSConnection object at 0x15045e710>: Failed to resolve 'us.i.posthog.com' ([Errno 8] nodename nor servname provided, or not known)")': /batch/
2025-06-19 16:41:46,041 | urllib3.connectionpool | DEBUG | connectionpool.py:1049 | Starting new HTTPS connection (26): us.i.posthog.com:443
2025-06-19 16:41:46,042 | urllib3.util.retry | DEBUG | retry.py:521 | Incremented Retry for (url='/batch/'): Retry(total=0, connect=0, read=2, redirect=None, status=None)
2025-06-19 16:41:46,042 | urllib3.connectionpool | WARNING | connectionpool.py:868 | Retrying (Retry(total=0, connect=0, read=2, redirect=None, status=None)) after connection broken by 'NameResolutionError("<urllib3.connection.HTTPSConnection object at 0x15045f9d0>: Failed to resolve 'us.i.posthog.com' ([Errno 8] nodename nor servname provided, or not known)")': /batch/
2025-06-19 16:41:46,042 | urllib3.connectionpool | DEBUG | connectionpool.py:1049 | Starting new HTTPS connection (27): us.i.posthog.com:443
2025-06-19 16:41:46,043 | backoff | INFO | _common.py:105 | Backing off send_request(...) for 0.8s (requests.exceptions.ConnectionError: HTTPSConnectionPool(host='us.i.posthog.com', port=443): Max retries exceeded with url: /batch/ (Caused by NameResolutionError("<urllib3.connection.HTTPSConnection object at 0x15045e850>: Failed to resolve 'us.i.posthog.com' ([Errno 8] nodename nor servname provided, or not known)")))
2025-06-19 16:41:46,856 | urllib3.connectionpool | DEBUG | connectionpool.py:1049 | Starting new HTTPS connection (28): us.i.posthog.com:443
2025-06-19 16:41:46,858 | urllib3.util.retry | DEBUG | retry.py:521 | Incremented Retry for (url='/batch/'): Retry(total=1, connect=1, read=2, redirect=None, status=None)
2025-06-19 16:41:46,858 | urllib3.connectionpool | WARNING | connectionpool.py:868 | Retrying (Retry(total=1, connect=1, read=2, redirect=None, status=None)) after connection broken by 'NameResolutionError("<urllib3.connection.HTTPSConnection object at 0x179aeac10>: Failed to resolve 'us.i.posthog.com' ([Errno 8] nodename nor servname provided, or not known)")': /batch/
2025-06-19 16:41:46,858 | urllib3.connectionpool | DEBUG | connectionpool.py:1049 | Starting new HTTPS connection (29): us.i.posthog.com:443
2025-06-19 16:41:46,858 | urllib3.util.retry | DEBUG | retry.py:521 | Incremented Retry for (url='/batch/'): Retry(total=0, connect=0, read=2, redirect=None, status=None)
2025-06-19 16:41:46,859 | urllib3.connectionpool | WARNING | connectionpool.py:868 | Retrying (Retry(total=0, connect=0, read=2, redirect=None, status=None)) after connection broken by 'NameResolutionError("<urllib3.connection.HTTPSConnection object at 0x179aea710>: Failed to resolve 'us.i.posthog.com' ([Errno 8] nodename nor servname provided, or not known)")': /batch/
2025-06-19 16:41:46,859 | urllib3.connectionpool | DEBUG | connectionpool.py:1049 | Starting new HTTPS connection (30): us.i.posthog.com:443
2025-06-19 16:41:46,859 | backoff | INFO | _common.py:105 | Backing off send_request(...) for 0.8s (requests.exceptions.ConnectionError: HTTPSConnectionPool(host='us.i.posthog.com', port=443): Max retries exceeded with url: /batch/ (Caused by NameResolutionError("<urllib3.connection.HTTPSConnection object at 0x179aeaad0>: Failed to resolve 'us.i.posthog.com' ([Errno 8] nodename nor servname provided, or not known)")))
2025-06-19 16:41:47,665 | urllib3.connectionpool | DEBUG | connectionpool.py:1049 | Starting new HTTPS connection (31): us.i.posthog.com:443
2025-06-19 16:41:47,666 | urllib3.util.retry | DEBUG | retry.py:521 | Incremented Retry for (url='/batch/'): Retry(total=1, connect=1, read=2, redirect=None, status=None)
2025-06-19 16:41:47,666 | urllib3.connectionpool | WARNING | connectionpool.py:868 | Retrying (Retry(total=1, connect=1, read=2, redirect=None, status=None)) after connection broken by 'NameResolutionError("<urllib3.connection.HTTPSConnection object at 0x179aeafd0>: Failed to resolve 'us.i.posthog.com' ([Errno 8] nodename nor servname provided, or not known)")': /batch/
2025-06-19 16:41:47,666 | urllib3.connectionpool | DEBUG | connectionpool.py:1049 | Starting new HTTPS connection (32): us.i.posthog.com:443
2025-06-19 16:41:47,667 | urllib3.util.retry | DEBUG | retry.py:521 | Incremented Retry for (url='/batch/'): Retry(total=0, connect=0, read=2, redirect=None, status=None)
2025-06-19 16:41:47,667 | urllib3.connectionpool | WARNING | connectionpool.py:868 | Retrying (Retry(total=0, connect=0, read=2, redirect=None, status=None)) after connection broken by 'NameResolutionError("<urllib3.connection.HTTPSConnection object at 0x179ae9810>: Failed to resolve 'us.i.posthog.com' ([Errno 8] nodename nor servname provided, or not known)")': /batch/
2025-06-19 16:41:47,667 | urllib3.connectionpool | DEBUG | connectionpool.py:1049 | Starting new HTTPS connection (33): us.i.posthog.com:443
2025-06-19 16:41:47,668 | backoff | INFO | _common.py:105 | Backing off send_request(...) for 3.3s (requests.exceptions.ConnectionError: HTTPSConnectionPool(host='us.i.posthog.com', port=443): Max retries exceeded with url: /batch/ (Caused by NameResolutionError("<urllib3.connection.HTTPSConnection object at 0x179ae9450>: Failed to resolve 'us.i.posthog.com' ([Errno 8] nodename nor servname provided, or not known)")))
2025-06-19 16:41:50,991 | urllib3.connectionpool | DEBUG | connectionpool.py:1049 | Starting new HTTPS connection (34): us.i.posthog.com:443
2025-06-19 16:41:50,992 | urllib3.util.retry | DEBUG | retry.py:521 | Incremented Retry for (url='/batch/'): Retry(total=1, connect=1, read=2, redirect=None, status=None)
2025-06-19 16:41:50,992 | urllib3.connectionpool | WARNING | connectionpool.py:868 | Retrying (Retry(total=1, connect=1, read=2, redirect=None, status=None)) after connection broken by 'NameResolutionError("<urllib3.connection.HTTPSConnection object at 0x179ae96d0>: Failed to resolve 'us.i.posthog.com' ([Errno 8] nodename nor servname provided, or not known)")': /batch/
2025-06-19 16:41:50,992 | urllib3.connectionpool | DEBUG | connectionpool.py:1049 | Starting new HTTPS connection (35): us.i.posthog.com:443
2025-06-19 16:41:50,993 | urllib3.util.retry | DEBUG | retry.py:521 | Incremented Retry for (url='/batch/'): Retry(total=0, connect=0, read=2, redirect=None, status=None)
2025-06-19 16:41:50,993 | urllib3.connectionpool | WARNING | connectionpool.py:868 | Retrying (Retry(total=0, connect=0, read=2, redirect=None, status=None)) after connection broken by 'NameResolutionError("<urllib3.connection.HTTPSConnection object at 0x179ae8550>: Failed to resolve 'us.i.posthog.com' ([Errno 8] nodename nor servname provided, or not known)")': /batch/
2025-06-19 16:41:50,993 | urllib3.connectionpool | DEBUG | connectionpool.py:1049 | Starting new HTTPS connection (36): us.i.posthog.com:443
2025-06-19 16:41:50,994 | backoff | ERROR | _common.py:120 | Giving up send_request(...) after 4 tries (requests.exceptions.ConnectionError: HTTPSConnectionPool(host='us.i.posthog.com', port=443): Max retries exceeded with url: /batch/ (Caused by NameResolutionError("<urllib3.connection.HTTPSConnection object at 0x179ae8690>: Failed to resolve 'us.i.posthog.com' ([Errno 8] nodename nor servname provided, or not known)")))
2025-06-19 16:41:59,276 | pynucleus | INFO | collector.py:61 | Ingested 3602 chunks from 16 files.
2025-06-19 16:41:59,276 | __main__ | INFO | run_pipeline.py:354 | ‚úÖ Successfully ingested documents into ChromaDB
