2025-06-19 23:06:57,018 | __main__ | INFO | run_pipeline.py:517 | ðŸš€ Starting interactive chat session
2025-06-19 23:06:57,018 | __main__ | INFO | run_pipeline.py:518 | ðŸ¤– Model ID: Qwen/Qwen2.5-1.5B-Instruct
2025-06-19 23:06:57,018 | __main__ | INFO | run_pipeline.py:519 | ðŸ“Š Top K: 5
2025-06-19 23:06:57,018 | __main__ | INFO | run_pipeline.py:532 | ðŸ”§ Initializing RAG pipeline and LLM runner
2025-06-19 23:06:57,019 | pynucleus.rag.vector_store | ERROR | vector_store.py:612 | Failed to initialize ChromaDB: An instance of Chroma already exists for data/vector_db with different settings
2025-06-19 23:06:57,019 | pynucleus.pipeline.pipeline_rag | WARNING | pipeline_rag.py:41 | Vector store (chroma) not fully loaded - will use fallback mode
2025-06-19 23:06:57,544 | urllib3.connectionpool | WARNING | connectionpool.py:868 | Retrying (Retry(total=1, connect=1, read=2, redirect=None, status=None)) after connection broken by 'NameResolutionError("<urllib3.connection.HTTPSConnection object at 0x1473978c0>: Failed to resolve 'us.i.posthog.com' ([Errno 8] nodename nor servname provided, or not known)")': /batch/
2025-06-19 23:06:57,545 | urllib3.connectionpool | WARNING | connectionpool.py:868 | Retrying (Retry(total=0, connect=0, read=2, redirect=None, status=None)) after connection broken by 'NameResolutionError("<urllib3.connection.HTTPSConnection object at 0x147c69310>: Failed to resolve 'us.i.posthog.com' ([Errno 8] nodename nor servname provided, or not known)")': /batch/
2025-06-19 23:06:57,559 | backoff | INFO | _common.py:105 | Backing off send_request(...) for 0.2s (requests.exceptions.ConnectionError: HTTPSConnectionPool(host='us.i.posthog.com', port=443): Max retries exceeded with url: /batch/ (Caused by NameResolutionError("<urllib3.connection.HTTPSConnection object at 0x147c69810>: Failed to resolve 'us.i.posthog.com' ([Errno 8] nodename nor servname provided, or not known)")))
2025-06-19 23:06:57,868 | urllib3.connectionpool | WARNING | connectionpool.py:868 | Retrying (Retry(total=1, connect=1, read=2, redirect=None, status=None)) after connection broken by 'NameResolutionError("<urllib3.connection.HTTPSConnection object at 0x1535e2490>: Failed to resolve 'us.i.posthog.com' ([Errno 8] nodename nor servname provided, or not known)")': /batch/
2025-06-19 23:06:57,869 | urllib3.connectionpool | WARNING | connectionpool.py:868 | Retrying (Retry(total=0, connect=0, read=2, redirect=None, status=None)) after connection broken by 'NameResolutionError("<urllib3.connection.HTTPSConnection object at 0x1535e2fd0>: Failed to resolve 'us.i.posthog.com' ([Errno 8] nodename nor servname provided, or not known)")': /batch/
2025-06-19 23:06:57,870 | backoff | INFO | _common.py:105 | Backing off send_request(...) for 1.5s (requests.exceptions.ConnectionError: HTTPSConnectionPool(host='us.i.posthog.com', port=443): Max retries exceeded with url: /batch/ (Caused by NameResolutionError("<urllib3.connection.HTTPSConnection object at 0x1535e3250>: Failed to resolve 'us.i.posthog.com' ([Errno 8] nodename nor servname provided, or not known)")))
2025-06-19 23:06:58,318 | pynucleus.llm.llm_runner | INFO | llm_runner.py:27 | Loading model: Qwen/Qwen2.5-1.5B-Instruct
2025-06-19 23:06:59,388 | urllib3.connectionpool | WARNING | connectionpool.py:868 | Retrying (Retry(total=1, connect=1, read=2, redirect=None, status=None)) after connection broken by 'NameResolutionError("<urllib3.connection.HTTPSConnection object at 0x16a925d10>: Failed to resolve 'us.i.posthog.com' ([Errno 8] nodename nor servname provided, or not known)")': /batch/
2025-06-19 23:06:59,389 | urllib3.connectionpool | WARNING | connectionpool.py:868 | Retrying (Retry(total=0, connect=0, read=2, redirect=None, status=None)) after connection broken by 'NameResolutionError("<urllib3.connection.HTTPSConnection object at 0x16aac87d0>: Failed to resolve 'us.i.posthog.com' ([Errno 8] nodename nor servname provided, or not known)")': /batch/
2025-06-19 23:06:59,390 | backoff | INFO | _common.py:105 | Backing off send_request(...) for 3.5s (requests.exceptions.ConnectionError: HTTPSConnectionPool(host='us.i.posthog.com', port=443): Max retries exceeded with url: /batch/ (Caused by NameResolutionError("<urllib3.connection.HTTPSConnection object at 0x16aac91d0>: Failed to resolve 'us.i.posthog.com' ([Errno 8] nodename nor servname provided, or not known)")))
2025-06-19 23:07:02,876 | urllib3.connectionpool | WARNING | connectionpool.py:868 | Retrying (Retry(total=1, connect=1, read=2, redirect=None, status=None)) after connection broken by 'NameResolutionError("<urllib3.connection.HTTPSConnection object at 0x16b88ead0>: Failed to resolve 'us.i.posthog.com' ([Errno 8] nodename nor servname provided, or not known)")': /batch/
2025-06-19 23:07:02,877 | urllib3.connectionpool | WARNING | connectionpool.py:868 | Retrying (Retry(total=0, connect=0, read=2, redirect=None, status=None)) after connection broken by 'NameResolutionError("<urllib3.connection.HTTPSConnection object at 0x16b88ed50>: Failed to resolve 'us.i.posthog.com' ([Errno 8] nodename nor servname provided, or not known)")': /batch/
2025-06-19 23:07:02,879 | backoff | ERROR | _common.py:120 | Giving up send_request(...) after 4 tries (requests.exceptions.ConnectionError: HTTPSConnectionPool(host='us.i.posthog.com', port=443): Max retries exceeded with url: /batch/ (Caused by NameResolutionError("<urllib3.connection.HTTPSConnection object at 0x16b88efd0>: Failed to resolve 'us.i.posthog.com' ([Errno 8] nodename nor servname provided, or not known)")))
2025-06-19 23:07:07,467 | pynucleus.llm.llm_runner | INFO | llm_runner.py:47 | Model loaded successfully on device: cpu
2025-06-19 23:07:20,537 | urllib3.connectionpool | WARNING | connectionpool.py:868 | Retrying (Retry(total=1, connect=1, read=2, redirect=None, status=None)) after connection broken by 'NameResolutionError("<urllib3.connection.HTTPSConnection object at 0x16b88f390>: Failed to resolve 'us.i.posthog.com' ([Errno 8] nodename nor servname provided, or not known)")': /batch/
2025-06-19 23:07:20,538 | urllib3.connectionpool | WARNING | connectionpool.py:868 | Retrying (Retry(total=0, connect=0, read=2, redirect=None, status=None)) after connection broken by 'NameResolutionError("<urllib3.connection.HTTPSConnection object at 0x16b88fd90>: Failed to resolve 'us.i.posthog.com' ([Errno 8] nodename nor servname provided, or not known)")': /batch/
2025-06-19 23:07:20,540 | backoff | INFO | _common.py:105 | Backing off send_request(...) for 0.2s (requests.exceptions.ConnectionError: HTTPSConnectionPool(host='us.i.posthog.com', port=443): Max retries exceeded with url: /batch/ (Caused by NameResolutionError("<urllib3.connection.HTTPSConnection object at 0x16ba9c050>: Failed to resolve 'us.i.posthog.com' ([Errno 8] nodename nor servname provided, or not known)")))
2025-06-19 23:07:20,791 | urllib3.connectionpool | WARNING | connectionpool.py:868 | Retrying (Retry(total=1, connect=1, read=2, redirect=None, status=None)) after connection broken by 'NameResolutionError("<urllib3.connection.HTTPSConnection object at 0x16ba9c550>: Failed to resolve 'us.i.posthog.com' ([Errno 8] nodename nor servname provided, or not known)")': /batch/
2025-06-19 23:07:20,793 | urllib3.connectionpool | WARNING | connectionpool.py:868 | Retrying (Retry(total=0, connect=0, read=2, redirect=None, status=None)) after connection broken by 'NameResolutionError("<urllib3.connection.HTTPSConnection object at 0x16ba9c7d0>: Failed to resolve 'us.i.posthog.com' ([Errno 8] nodename nor servname provided, or not known)")': /batch/
2025-06-19 23:07:20,805 | backoff | INFO | _common.py:105 | Backing off send_request(...) for 1.9s (requests.exceptions.ConnectionError: HTTPSConnectionPool(host='us.i.posthog.com', port=443): Max retries exceeded with url: /batch/ (Caused by NameResolutionError("<urllib3.connection.HTTPSConnection object at 0x16ba9ca50>: Failed to resolve 'us.i.posthog.com' ([Errno 8] nodename nor servname provided, or not known)")))
2025-06-19 23:07:22,707 | urllib3.connectionpool | WARNING | connectionpool.py:868 | Retrying (Retry(total=1, connect=1, read=2, redirect=None, status=None)) after connection broken by 'NameResolutionError("<urllib3.connection.HTTPSConnection object at 0x16ba9cf50>: Failed to resolve 'us.i.posthog.com' ([Errno 8] nodename nor servname provided, or not known)")': /batch/
2025-06-19 23:07:22,718 | urllib3.connectionpool | WARNING | connectionpool.py:868 | Retrying (Retry(total=0, connect=0, read=2, redirect=None, status=None)) after connection broken by 'NameResolutionError("<urllib3.connection.HTTPSConnection object at 0x16ba9d090>: Failed to resolve 'us.i.posthog.com' ([Errno 8] nodename nor servname provided, or not known)")': /batch/
2025-06-19 23:07:22,727 | backoff | INFO | _common.py:105 | Backing off send_request(...) for 2.6s (requests.exceptions.ConnectionError: HTTPSConnectionPool(host='us.i.posthog.com', port=443): Max retries exceeded with url: /batch/ (Caused by NameResolutionError("<urllib3.connection.HTTPSConnection object at 0x16ba9d450>: Failed to resolve 'us.i.posthog.com' ([Errno 8] nodename nor servname provided, or not known)")))
2025-06-19 23:07:25,327 | urllib3.connectionpool | WARNING | connectionpool.py:868 | Retrying (Retry(total=1, connect=1, read=2, redirect=None, status=None)) after connection broken by 'NameResolutionError("<urllib3.connection.HTTPSConnection object at 0x16ba9d950>: Failed to resolve 'us.i.posthog.com' ([Errno 8] nodename nor servname provided, or not known)")': /batch/
2025-06-19 23:07:25,330 | urllib3.connectionpool | WARNING | connectionpool.py:868 | Retrying (Retry(total=0, connect=0, read=2, redirect=None, status=None)) after connection broken by 'NameResolutionError("<urllib3.connection.HTTPSConnection object at 0x16ba9dbd0>: Failed to resolve 'us.i.posthog.com' ([Errno 8] nodename nor servname provided, or not known)")': /batch/
2025-06-19 23:07:25,343 | backoff | ERROR | _common.py:120 | Giving up send_request(...) after 4 tries (requests.exceptions.ConnectionError: HTTPSConnectionPool(host='us.i.posthog.com', port=443): Max retries exceeded with url: /batch/ (Caused by NameResolutionError("<urllib3.connection.HTTPSConnection object at 0x16ba9de50>: Failed to resolve 'us.i.posthog.com' ([Errno 8] nodename nor servname provided, or not known)")))
2025-06-19 23:07:56,011 | pynucleus.llm.llm_runner | INFO | llm_runner.py:201 | Generated response in 29.26s
